Workbook

Sheet crm_transaction_log
A1: Reservation_Date | B1: Reservation_Time | C1: Chart_No | D1: Is_First_Visit | E1: Inflow_Channel | F1: Consultant_ID | G1: Reservation_Status | H1: Treatment_Item | I1: Payment_Amount | J1: Unpaid_Amount | K1: 검증
A2: 46310 | B2: 0.42708333 | C2: C250011 | D2: N | E2: 카카오톡 | F2: CS_01 | G2: 진료완료 | H2: 피코토닝 10회 | I2: 850000 | J2: 0 | K2: =VLOOKUP($C2,customer_master!$A$2:$F$21,1,0) -> C250011 | L2: =IF(OR(G2="예약취소", G2="노쇼"), I2=0, TRUE) -> TRUE | M2: =IF(OR(G2="예약취소", G2="노쇼"), IF(AND(I2=0, J2=0), TRUE, FALSE), TRUE) -> TRUE
A3: 46310 | B3: 0.44444444 | C3: C250012 | D3: N | E3: 재방문 | F3: CS_02 | G3: 진료완료 | H3: 사각턱보톡스 | I3: 45000 | J3: 0 | K3: =VLOOKUP($C3,customer_master!$A$2:$F$21,1,0) -> C250012 | L3: =IF(OR(G3="예약취소", G3="노쇼"), I3=0, TRUE) -> TRUE | M3: =IF(OR(G3="예약취소", G3="노쇼"), IF(AND(I3=0, J3=0), TRUE, FALSE), TRUE) -> TRUE
A4: 46310 | B4: 0.45833333 | C4: C250013 | D4: Y | E4: 지인추천 | F4: CS_01 | G4: 노쇼 | H4: 입술필러 | I4: 0 | J4: 0 | K4: =VLOOKUP($C4,customer_master!$A$2:$F$21,1,0) -> C250013 | L4: =IF(OR(G4="예약취소", G4="노쇼"), I4=0, TRUE) -> TRUE | M4: =IF(OR(G4="예약취소", G4="노쇼"), IF(AND(I4=0, J4=0), TRUE, FALSE), TRUE) -> TRUE
A5: 46310 | B5: 0.47222222 | C5: C250014 | D5: N | E5: 인스타그램 | F5: CS_03 | G5: 진료완료 | H5: 울쎄라 300샷 | I5: 1200000 | J5: 300000 | K5: =VLOOKUP($C5,customer_master!$A$2:$F$21,1,0) -> C250014 | L5: =IF(OR(G5="예약취소", G5="노쇼"), I5=0, TRUE) -> TRUE | M5: =IF(OR(G5="예약취소", G5="노쇼"), IF(AND(I5=0, J5=0), TRUE, FALSE), TRUE) -> TRUE
A6: 46310 | B6: 0.5 | C6: C250015 | D6: Y | E6: 네이버검색 | F6: CS_02 | G6: 진료완료 | H6: 리쥬란힐러 2cc | I6: 290000 | J6: 0 | K6: =VLOOKUP($C6,customer_master!$A$2:$F$21,1,0) -> C250015 | L6: =IF(OR(G6="예약취소", G6="노쇼"), I6=0, TRUE) -> TRUE | M6: =IF(OR(G6="예약취소", G6="노쇼"), IF(AND(I6=0, J6=0), TRUE, FALSE), TRUE) -> TRUE
A7: 46310 | B7: 0.52083333 | C7: C250016 | D7: N | E7: 재방문 | F7: CS_01 | G7: 진료완료 | H7: 겨드랑이제모 5회 | I7: 39000 | J7: 0 | K7: =VLOOKUP($C7,customer_master!$A$2:$F$21,1,0) -> C250016 | L7: =IF(OR(G7="예약취소", G7="노쇼"), I7=0, TRUE) -> TRUE | M7: =IF(OR(G7="예약취소", G7="노쇼"), IF(AND(I7=0, J7=0), TRUE, FALSE), TRUE) -> TRUE
A8: 46310 | B8: 0.58333333 | C8: C250017 | D8: Y | E8: 당근마켓 | F8: CS_03 | G8: 예약취소 | H8: 슈링크 400샷 | I8: 0 | J8: 0 | K8: =VLOOKUP($C8,customer_master!$A$2:$F$21,1,0) -> C250017 | L8: =IF(OR(G8="예약취소", G8="노쇼"), I8=0, TRUE) -> TRUE | M8: =IF(OR(G8="예약취소", G8="노쇼"), IF(AND(I8=0, J8=0), TRUE, FALSE), TRUE) -> TRUE
A9: 46310 | B9: 0.59722222 | C9: C250018 | D9: N | E9: 카카오톡 | F9: CS_02 | G9: 진료완료 | H9: 미간보톡스 | I9: 35000 | J9: 0 | K9: =VLOOKUP($C9,customer_master!$A$2:$F$21,1,0) -> C250018 | L9: =IF(OR(G9="예약취소", G9="노쇼"), I9=0, TRUE) -> TRUE | M9: =IF(OR(G9="예약취소", G9="노쇼"), IF(AND(I9=0, J9=0), TRUE, FALSE), TRUE) -> TRUE
A10: 46310 | B10: 0.63541667 | C10: C250020 | D10: N | E10: 지인추천 | F10: CS_03 | G10: 진료완료 | H10: 인모드 FORMA | I10: 150000 | J10: 0 | K10: =VLOOKUP($C10,customer_master!$A$2:$F$21,1,0) -> C250020 | L10: =IF(OR(G10="예약취소", G10="노쇼"), I10=0, TRUE) -> TRUE | M10: =IF(OR(G10="예약취소", G10="노쇼"), IF(AND(I10=0, J10=0), TRUE, FALSE), TRUE) -> TRUE
A11: 46310 | B11: 0.65277778 | C11: C260021 | D11: Y | E11: 네이버검색 | F11: CS_01 | G11: 노쇼 | H11: 아쿠아필 | I11: 0 | J11: 0 | K11: =VLOOKUP($C11,customer_master!$A$2:$F$21,1,0) -> C260021 | L11: =IF(OR(G11="예약취소", G11="노쇼"), I11=0, TRUE) -> TRUE | M11: =IF(OR(G11="예약취소", G11="노쇼"), IF(AND(I11=0, J11=0), TRUE, FALSE), TRUE) -> TRUE
A12: 46310 | B12: 0.66666667 | C12: C260022 | D12: N | E12: 재방문 | F12: CS_02 | G12: 예약취소 | H12: 피코토닝 10회 | I12: 0 | J12: 0 | K12: =VLOOKUP($C12,customer_master!$A$2:$F$21,1,0) -> C260022 | L12: =IF(OR(G12="예약취소", G12="노쇼"), I12=0, TRUE) -> TRUE | M12: =IF(OR(G12="예약취소", G12="노쇼"), IF(AND(I12=0, J12=0), TRUE, FALSE), TRUE) -> TRUE | N12: 금액삭제(예약취소)
A13: 46310 | B13: 0.68055556 | C13: C260023 | D13: Y | E13: 카카오톡 | F13: CS_03 | G13: 진료완료 | H13: 사각턱보톡스 | I13: 45000 | J13: 0 | K13: =VLOOKUP($C13,customer_master!$A$2:$F$21,1,0) -> C260023 | L13: =IF(OR(G13="예약취소", G13="노쇼"), I13=0, TRUE) -> TRUE | M13: =IF(OR(G13="예약취소", G13="노쇼"), IF(AND(I13=0, J13=0), TRUE, FALSE), TRUE) -> TRUE
A14: 46310 | B14: 0.70833333 | C14: C260024 | D14: N | E14: 지인추천 | F14: CS_01 | G14: 진료완료 | H14: 여드름스케일링 | I14: 60000 | J14: 0 | K14: =VLOOKUP($C14,customer_master!$A$2:$F$21,1,0) -> C260024 | L14: =IF(OR(G14="예약취소", G14="노쇼"), I14=0, TRUE) -> TRUE | M14: =IF(OR(G14="예약취소", G14="노쇼"), IF(AND(I14=0, J14=0), TRUE, FALSE), TRUE) -> TRUE
A15: 46310 | B15: 0.72916667 | C15: C260025 | D15: Y | E15: 인스타그램 | F15: CS_02 | G15: 진료완료 | H15: 팔자필러 | I15: 220000 | J15: 0 | K15: =VLOOKUP($C15,customer_master!$A$2:$F$21,1,0) -> C260025 | L15: =IF(OR(G15="예약취소", G15="노쇼"), I15=0, TRUE) -> TRUE | M15: =IF(OR(G15="예약취소", G15="노쇼"), IF(AND(I15=0, J15=0), TRUE, FALSE), TRUE) -> TRUE
A16: 46310 | B16: 0.75 | C16: C260026 | D16: N | E16: 재방문 | F16: CS_03 | G16: 진료완료 | H16: 써마지 600샷 | I16: 0 | J16: 0 | K16: =VLOOKUP($C16,customer_master!$A$2:$F$21,1,0) -> C260026 | L16: =IF(OR(G16="예약취소", G16="노쇼"), I16=0, TRUE) -> TRUE | M16: =IF(OR(G16="예약취소", G16="노쇼"), IF(AND(I16=0, J16=0), TRUE, FALSE), TRUE) -> TRUE
A17: 46311 | B17: 0.41666667 | C17: C260027 | D17: Y | E17: 당근마켓 | F17: CS_01 | G17: 진료완료 | H17: 쥬베룩 볼륨 | I17: 450000 | J17: 0 | K17: =VLOOKUP($C17,customer_master!$A$2:$F$21,1,0) -> C260027 | L17: =IF(OR(G17="예약취소", G17="노쇼"), I17=0, TRUE) -> TRUE | M17: =IF(OR(G17="예약취소", G17="노쇼"), IF(AND(I17=0, J17=0), TRUE, FALSE), TRUE) -> TRUE
A18: 46311 | B18: 0.4375 | C18: C260028 | D18: N | E18: 네이버검색 | F18: CS_02 | G18: 진료완료 | H18: 피코프락셀 | I18: 120000 | J18: 0 | K18: =VLOOKUP($C18,customer_master!$A$2:$F$21,1,0) -> C260028 | L18: =IF(OR(G18="예약취소", G18="노쇼"), I18=0, TRUE) -> TRUE | M18: =IF(OR(G18="예약취소", G18="노쇼"), IF(AND(I18=0, J18=0), TRUE, FALSE), TRUE) -> TRUE
A19: 46311 | B19: 0.46875 | C19: C260029 | D19: Y | E19: 지인추천 | F19: CS_03 | G19: 노쇼 | H19: 종아리보톡스 | I19: 0 | J19: 0 | K19: =VLOOKUP($C19,customer_master!$A$2:$F$21,1,0) -> C260029 | L19: =IF(OR(G19="예약취소", G19="노쇼"), I19=0, TRUE) -> TRUE | M19: =IF(OR(G19="예약취소", G19="노쇼"), IF(AND(I19=0, J19=0), TRUE, FALSE), TRUE) -> TRUE
A20: 46311 | B20: 0.48958333 | C20: C260030 | D20: N | E20: 재방문 | F20: CS_01 | G20: 진료완료 | H20: 애교필러 | I20: 150000 | J20: 0 | K20: =VLOOKUP($C20,customer_master!$A$2:$F$21,1,0) -> C260030 | L20: =IF(OR(G20="예약취소", G20="노쇼"), I20=0, TRUE) -> TRUE | M20: =IF(OR(G20="예약취소", G20="노쇼"), IF(AND(I20=0, J20=0), TRUE, FALSE), TRUE) -> TRUE
A21: 46311 | B21: 0.52083333 | C21: C250011 | D21: Y | E21: 카카오톡 | F21: CS_02 | G21: 진료완료 | H21: 울쎄라 300샷 | I21: 1200000 | J21: 0 | K21: =VLOOKUP($C21,customer_master!$A$2:$F$21,1,0) -> C250011 | L21: =IF(OR(G21="예약취소", G21="노쇼"), I21=0, TRUE) -> TRUE | M21: =IF(OR(G21="예약취소", G21="노쇼"), IF(AND(I21=0, J21=0), TRUE, FALSE), TRUE) -> TRUE
A22: 46311 | B22: 0.58333333 | C22: C250012 | D22: N | E22: 인스타그램 | F22: CS_03 | G22: 예약취소 | H22: 인중제모 | I22: 0 | J22: 0 | K22: =VLOOKUP($C22,customer_master!$A$2:$F$21,1,0) -> C250012 | L22: =IF(OR(G22="예약취소", G22="노쇼"), I22=0, TRUE) -> TRUE | M22: =IF(OR(G22="예약취소", G22="노쇼"), IF(AND(I22=0, J22=0), TRUE, FALSE), TRUE) -> TRUE
A23: 46311 | B23: 0.61111111 | C23: C250013 | D23: Y | E23: 네이버검색 | F23: CS_01 | G23: 진료완료 | H23: 피코토닝 10회 | I23: 850000 | J23: 50000 | K23: =VLOOKUP($C23,customer_master!$A$2:$F$21,1,0) -> C250013 | L23: =IF(OR(G23="예약취소", G23="노쇼"), I23=0, TRUE) -> TRUE | M23: =IF(OR(G23="예약취소", G23="노쇼"), IF(AND(I23=0, J23=0), TRUE, FALSE), TRUE) -> TRUE
A24: 46311 | B24: 0.625 | C24: C250014 | D24: N | E24: 지인추천 | F24: CS_02 | G24: 진료완료 | H24: 사각턱보톡스 | I24: 45000 | J24: 0 | K24: =VLOOKUP($C24,customer_master!$A$2:$F$21,1,0) -> C250014 | L24: =IF(OR(G24="예약취소", G24="노쇼"), I24=0, TRUE) -> TRUE | M24: =IF(OR(G24="예약취소", G24="노쇼"), IF(AND(I24=0, J24=0), TRUE, FALSE), TRUE) -> TRUE
A25: 46311 | B25: 0.63888889 | C25: C250015 | D25: Y | E25: 당근마켓 | F25: CS_03 | G25: 진료완료 | H25: 입술필러 | I25: 200000 | J25: 0 | K25: =VLOOKUP($C25,customer_master!$A$2:$F$21,1,0) -> C250015 | L25: =IF(OR(G25="예약취소", G25="노쇼"), I25=0, TRUE) -> TRUE | M25: =IF(OR(G25="예약취소", G25="노쇼"), IF(AND(I25=0, J25=0), TRUE, FALSE), TRUE) -> TRUE | N25: 잔금 수정
A26: 46311 | B26: 0.66666667 | C26: C250016 | D26: N | E26: 카카오톡 | F26: CS_01 | G26: 진료완료 | H26: 인모드 FX | I26: 120000 | J26: 0 | K26: =VLOOKUP($C26,customer_master!$A$2:$F$21,1,0) -> C250016 | L26: =IF(OR(G26="예약취소", G26="노쇼"), I26=0, TRUE) -> TRUE | M26: =IF(OR(G26="예약취소", G26="노쇼"), IF(AND(I26=0, J26=0), TRUE, FALSE), TRUE) -> TRUE
A27: 46311 | B27: 0.6875 | C27: C250017 | D27: Y | E27: 재방문 | F27: CS_02 | G27: 예약취소 | H27: 리쥬란힐러 2cc | I27: 0 | J27: 0 | K27: =VLOOKUP($C27,customer_master!$A$2:$F$21,1,0) -> C250017 | L27: =IF(OR(G27="예약취소", G27="노쇼"), I27=0, TRUE) -> TRUE | M27: =IF(OR(G27="예약취소", G27="노쇼"), IF(AND(I27=0, J27=0), TRUE, FALSE), TRUE) -> TRUE | N27: 잔금삭제
A28: 46311 | B28: 0.70833333 | C28: C250018 | D28: N | E28: 네이버검색 | F28: CS_03 | G28: 노쇼 | H28: 겨드랑이제모 5회 | I28: 0 | J28: 0 | K28: =VLOOKUP($C28,customer_master!$A$2:$F$21,1,0) -> C250018 | L28: =IF(OR(G28="예약취소", G28="노쇼"), I28=0, TRUE) -> TRUE | M28: =IF(OR(G28="예약취소", G28="노쇼"), IF(AND(I28=0, J28=0), TRUE, FALSE), TRUE) -> TRUE
A29: 46311 | B29: 0.73611111 | C29: C250019 | D29: Y | E29: 지인추천 | F29: CS_01 | G29: 진료완료 | H29: 피코프락셀 | I29: 120000 | J29: 0 | K29: =VLOOKUP($C29,customer_master!$A$2:$F$21,1,0) -> C250019 | L29: =IF(OR(G29="예약취소", G29="노쇼"), I29=0, TRUE) -> TRUE | M29: =IF(OR(G29="예약취소", G29="노쇼"), IF(AND(I29=0, J29=0), TRUE, FALSE), TRUE) -> TRUE
A30: 46312 | B30: 0.41666667 | C30: C250020 | D30: N | E30: 인스타그램 | F30: CS_02 | G30: 진료완료 | H30: 미간보톡스 | I30: 35000 | J30: 0 | K30: =VLOOKUP($C30,customer_master!$A$2:$F$21,1,0) -> C250020 | L30: =IF(OR(G30="예약취소", G30="노쇼"), I30=0, TRUE) -> TRUE | M30: =IF(OR(G30="예약취소", G30="노쇼"), IF(AND(I30=0, J30=0), TRUE, FALSE), TRUE) -> TRUE
A31: 46312 | B31: 0.42708333 | C31: C260021 | D31: Y | E31: 카카오톡 | F31: CS_03 | G31: 진료완료 | H31: 코필러 | I31: 180000 | J31: 50000 | K31: =VLOOKUP($C31,customer_master!$A$2:$F$21,1,0) -> C260021 | L31: =IF(OR(G31="예약취소", G31="노쇼"), I31=0, TRUE) -> TRUE | M31: =IF(OR(G31="예약취소", G31="노쇼"), IF(AND(I31=0, J31=0), TRUE, FALSE), TRUE) -> TRUE
A32: 46312 | B32: 0.45833333 | C32: C260022 | D32: N | E32: 재방문 | F32: CS_01 | G32: 진료완료 | H32: 울쎄라 600샷 | I32: 2200000 | J32: 0 | K32: =VLOOKUP($C32,customer_master!$A$2:$F$21,1,0) -> C260022 | L32: =IF(OR(G32="예약취소", G32="노쇼"), I32=0, TRUE) -> TRUE | M32: =IF(OR(G32="예약취소", G32="노쇼"), IF(AND(I32=0, J32=0), TRUE, FALSE), TRUE) -> TRUE
A33: 46312 | B33: 0.47916667 | C33: C260023 | D33: Y | E33: 네이버검색 | F33: CS_02 | G33: 예약취소 | H33: 슈링크 400샷 | I33: 0 | J33: 0 | K33: =VLOOKUP($C33,customer_master!$A$2:$F$21,1,0) -> C260023 | L33: =IF(OR(G33="예약취소", G33="노쇼"), I33=0, TRUE) -> TRUE | M33: =IF(OR(G33="예약취소", G33="노쇼"), IF(AND(I33=0, J33=0), TRUE, FALSE), TRUE) -> TRUE
A34: 46312 | B34: 0.5 | C34: C260024 | D34: N | E34: 지인추천 | F34: CS_03 | G34: 진료완료 | H34: 종아리제모 | I34: 80000 | J34: 0 | K34: =VLOOKUP($C34,customer_master!$A$2:$F$21,1,0) -> C260024 | L34: =IF(OR(G34="예약취소", G34="노쇼"), I34=0, TRUE) -> TRUE | M34: =IF(OR(G34="예약취소", G34="노쇼"), IF(AND(I34=0, J34=0), TRUE, FALSE), TRUE) -> TRUE
A35: 46312 | B35: 0.54166667 | C35: C260025 | D35: Y | E35: 당근마켓 | F35: CS_01 | G35: 노쇼 | H35: 피코토닝 10회 | I35: 0 | J35: 0 | K35: =VLOOKUP($C35,customer_master!$A$2:$F$21,1,0) -> C260025 | L35: =IF(OR(G35="예약취소", G35="노쇼"), I35=0, TRUE) -> TRUE | M35: =IF(OR(G35="예약취소", G35="노쇼"), IF(AND(I35=0, J35=0), TRUE, FALSE), TRUE) -> TRUE
A36: 46312 | B36: 0.5625 | C36: C260026 | D36: N | E36: 카카오톡 | F36: CS_02 | G36: 진료완료 | H36: 사각턱보톡스 | I36: 45000 | J36: 0 | K36: =VLOOKUP($C36,customer_master!$A$2:$F$21,1,0) -> C260026 | L36: =IF(OR(G36="예약취소", G36="노쇼"), I36=0, TRUE) -> TRUE | M36: =IF(OR(G36="예약취소", G36="노쇼"), IF(AND(I36=0, J36=0), TRUE, FALSE), TRUE) -> TRUE
A37: 46312 | B37: 0.58333333 | C37: C260027 | D37: Y | E37: 재방문 | F37: CS_03 | G37: 진료완료 | H37: 팔자필러 | I37: 220000 | J37: 0 | K37: =VLOOKUP($C37,customer_master!$A$2:$F$21,1,0) -> C260027 | L37: =IF(OR(G37="예약취소", G37="노쇼"), I37=0, TRUE) -> TRUE | M37: =IF(OR(G37="예약취소", G37="노쇼"), IF(AND(I37=0, J37=0), TRUE, FALSE), TRUE) -> TRUE
A38: 46312 | B38: 0.61458333 | C38: C260028 | D38: N | E38: 인스타그램 | F38: CS_01 | G38: 진료완료 | H38: 써마지 600샷 | I38: 2500000 | J38: 500000 | K38: =VLOOKUP($C38,customer_master!$A$2:$F$21,1,0) -> C260028 | L38: =IF(OR(G38="예약취소", G38="노쇼"), I38=0, TRUE) -> TRUE | M38: =IF(OR(G38="예약취소", G38="노쇼"), IF(AND(I38=0, J38=0), TRUE, FALSE), TRUE) -> TRUE
A39: 46312 | B39: 0.63541667 | C39: C260029 | D39: Y | E39: 지인추천 | F39: CS_02 | G39: 진료완료 | H39: 쥬베룩 볼륨 | I39: 450000 | J39: 0 | K39: =VLOOKUP($C39,customer_master!$A$2:$F$21,1,0) -> C260029 | L39: =IF(OR(G39="예약취소", G39="노쇼"), I39=0, TRUE) -> TRUE | M39: =IF(OR(G39="예약취소", G39="노쇼"), IF(AND(I39=0, J39=0), TRUE, FALSE), TRUE) -> TRUE
A40: 46312 | B40: 0.66666667 | C40: C250011 | D40: Y | E40: 카카오톡 | F40: CS_01 | G40: 진료완료 | H40: 피코프락셀 | I40: 120000 | J40: 0 | K40: =VLOOKUP($C40,customer_master!$A$2:$F$21,1,0) -> C250011 | L40: =IF(OR(G40="예약취소", G40="노쇼"), I40=0, TRUE) -> TRUE | M40: =IF(OR(G40="예약취소", G40="노쇼"), IF(AND(I40=0, J40=0), TRUE, FALSE), TRUE) -> TRUE
...

Sheet customer_master
A1: Chart_No | B1: Customer_ID | C1: Customer_Name | D1: Phone_Number | E1: Customer_Grade | F1: Join_Date
A2: C250011 | B2: U1011 | C2: 김*수 | D2: 010-1234-5678 | E2: VIP | F2: 45667
A3: C250012 | B3: U1012 | C3: 이*영 | D3: 010-2345-6789 | E3: 일반 | F3: 45703
A4: C250013 | B4: U1013 | C4: 박*진 | D4: 010-3456-7890 | E4: 우수 | F4: 45717
A5: C250014 | B5: U1014 | C5: 최*훈 | D5: 010-4567-8901 | E5: 일반 | F5: 45757
A6: C250015 | B6: U1015 | C6: 정*아 | D6: 010-5678-9012 | E6: VIP | F6: 45782
A7: C250016 | B7: U1016 | C7: 강*석 | D7: 010-6789-0123 | E7: 우수 | F7: 45828
A8: C250017 | B8: U1017 | C8: 조*희 | D8: 010-7890-1234 | E8: 일반 | F8: 45839
A9: C250018 | B9: U1018 | C9: 윤*미 | D9: 010-8901-2345 | E9: 일반 | F9: 45884
A10: C250019 | B10: U1019 | C10: 장*민 | D10: 010-9012-3456 | E10: 우수 | F10: 45901
A11: C250020 | B11: U1020 | C11: 임*주 | D11: 010-0123-4567 | E11: VIP | F11: 45940
A12: C260021 | B12: U1021 | C12: 한*수 | D12: 010-1111-2222 | E12: 일반 | F12: 46027
A13: C260022 | B13: U1022 | C13: 오*연 | D13: 010-2222-3333 | E13: 일반 | F13: 46067
... A21: C260030 | B21: U1030 | C21: 고*석 | D21: 010-0000-1111 | E21: 우수 | F21: 46296

Sheet RAW_DATA
A1: Reservation_Date | B1: Reservation_Time | C1: Chart_No | D1: Is_First_Visit | E1: Inflow_Channel | F1: Consultant_ID | G1: Reservation_Status | H1: Treatment_Item | I1: Payment_Amount | J1: Unpaid_Amount | K1: 검증
A2: 46310 | B2: 0.42708333 | C2: C250011 | D2: N | E2: 카카오톡 | F2: CS_01 | G2: 진료완료 | H2: 피코토닝 10회 | I2: 850000 | J2: 0 | K2: =VLOOKUP($C2,customer_master!$A$2:$F$21,1,0) -> C250011 | L2: =IF(OR(G2="예약취소", G2="노쇼"), I2=0, TRUE) -> TRUE | M2: =IF(OR(G2="예약취소", G2="노쇼"), IF(AND(I2=0, J2=0), TRUE, FALSE), TRUE) -> TRUE
A3: 46310 | B3: 0.44444444 | C3: C250012 | D3: N | E3: 재방문 | F3: CS_02 | G3: 진료완료 | H3: 사각턱보톡스 | I3: 45000 | J3: 0 | K3: =VLOOKUP($C3,customer_master!$A$2:$F$21,1,0) -> C250012 | L3: =IF(OR(G3="예약취소", G3="노쇼"), I3=0, TRUE) -> TRUE | M3: =IF(OR(G3="예약취소", G3="노쇼"), IF(AND(I3=0, J3=0), TRUE, FALSE), TRUE) -> TRUE
A4: 46310 | B4: 0.45833333 | C4: C250013 | D4: Y | E4: 지인추천 | F4: CS_01 | G4: 노쇼 | H4: 입술필러 | I4: 0 | J4: 0 | K4: =VLOOKUP($C4,customer_master!$A$2:$F$21,1,0) -> C250013 | L4: =IF(OR(G4="예약취소", G4="노쇼"), I4=0, TRUE) -> TRUE | M4: =IF(OR(G4="예약취소", G4="노쇼"), IF(AND(I4=0, J4=0), TRUE, FALSE), TRUE) -> TRUE
A5: 46310 | B5: 0.47222222 | C5: C250014 | D5: N | E5: 인스타그램 | F5: CS_03 | G5: 진료완료 | H5: 울쎄라 300샷 | I5: 1200000 | J5: 300000 | K5: =VLOOKUP($C5,customer_master!$A$2:$F$21,1,0) -> C250014 | L5: =IF(OR(G5="예약취소", G5="노쇼"), I5=0, TRUE) -> TRUE | M5: =IF(OR(G5="예약취소", G5="노쇼"), IF(AND(I5=0, J5=0), TRUE, FALSE), TRUE) -> TRUE
A6: 46310 | B6: 0.5 | C6: C250015 | D6: Y | E6: 네이버검색 | F6: CS_02 | G6: 진료완료 | H6: 리쥬란힐러 2cc | I6: 290000 | J6: 0 | K6: =VLOOKUP($C6,customer_master!$A$2:$F$21,1,0) -> C250015 | L6: =IF(OR(G6="예약취소", G6="노쇼"), I6=0, TRUE) -> TRUE | M6: =IF(OR(G6="예약취소", G6="노쇼"), IF(AND(I6=0, J6=0), TRUE, FALSE), TRUE) -> TRUE
A7: 46310 | B7: 0.52083333 | C7: C250016 | D7: N | E7: 재방문 | F7: CS_01 | G7: 진료완료 | H7: 겨드랑이제모 5회 | I7: 39000 | J7: 0 | K7: =VLOOKUP($C7,customer_master!$A$2:$F$21,1,0) -> C250016 | L7: =IF(OR(G7="예약취소", G7="노쇼"), I7=0, TRUE) -> TRUE | M7: =IF(OR(G7="예약취소", G7="노쇼"), IF(AND(I7=0, J7=0), TRUE, FALSE), TRUE) -> TRUE
A8: 46310 | B8: 0.58333333 | C8: C250017 | D8: Y | E8: 당근마켓 | F8: CS_03 | G8: 예약취소 | H8: 슈링크 400샷 | I8: 0 | J8: 0 | K8: =VLOOKUP($C8,customer_master!$A$2:$F$21,1,0) -> C250017 | L8: =IF(OR(G8="예약취소", G8="노쇼"), I8=0, TRUE) -> TRUE | M8: =IF(OR(G8="예약취소", G8="노쇼"), IF(AND(I8=0, J8=0), TRUE, FALSE), TRUE) -> TRUE
A9: 46310 | B9: 0.59722222 | C9: C250018 | D9: N | E9: 카카오톡 | F9: CS_02 | G9: 진료완료 | H9: 미간보톡스 | I9: 35000 | J9: 0 | K9: =VLOOKUP($C9,customer_master!$A$2:$F$21,1,0) -> C250018 | L9: =IF(OR(G9="예약취소", G9="노쇼"), I9=0, TRUE) -> TRUE | M9: =IF(OR(G9="예약취소", G9="노쇼"), IF(AND(I9=0, J9=0), TRUE, FALSE), TRUE) -> TRUE
A10: 46310 | B10: 0.63541667 | C10: C250020 | D10: N | E10: 지인추천 | F10: CS_03 | G10: 진료완료 | H10: 인모드 FORMA | I10: 150000 | J10: 0 | K10: =VLOOKUP($C10,customer_master!$A$2:$F$21,1,0) -> C250020 | L10: =IF(OR(G10="예약취소", G10="노쇼"), I10=0, TRUE) -> TRUE | M10: =IF(OR(G10="예약취소", G10="노쇼"), IF(AND(I10=0, J10=0), TRUE, FALSE), TRUE) -> TRUE
A11: 46310 | B11: 0.65277778 | C11: C260021 | D11: Y | E11: 네이버검색 | F11: CS_01 | G11: 노쇼 | H11: 아쿠아필 | I11: 0 | J11: 0 | K11: =VLOOKUP($C11,customer_master!$A$2:$F$21,1,0) -> C260021 | L11: =IF(OR(G11="예약취소", G11="노쇼"), I11=0, TRUE) -> TRUE | M11: =IF(OR(G11="예약취소", G11="노쇼"), IF(AND(I11=0, J11=0), TRUE, FALSE), TRUE) -> TRUE
A12: 46310 | B12: 0.66666667 | C12: C260022 | D12: N | E12: 재방문 | F12: CS_02 | G12: 예약취소 | H12: 피코토닝 10회 | I12: 0 | J12: 0 | K12: =VLOOKUP($C12,customer_master!$A$2:$F$21,1,0) -> C260022 | L12: =IF(OR(G12="예약취소", G12="노쇼"), I12=0, TRUE) -> TRUE | M12: =IF(OR(G12="예약취소", G12="노쇼"), IF(AND(I12=0, J12=0), TRUE, FALSE), TRUE) -> TRUE | N12: 금액삭제(예약취소)
A13: 46310 | B13: 0.68055556 | C13: C260023 | D13: Y | E13: 카카오톡 | F13: CS_03 | G13: 진료완료 | H13: 사각턱보톡스 | I13: 45000 | J13: 0 | K13: =VLOOKUP($C13,customer_master!$A$2:$F$21,1,0) -> C260023 | L13: =IF(OR(G13="예약취소", G13="노쇼"), I13=0, TRUE) -> TRUE | M13: =IF(OR(G13="예약취소", G13="노쇼"), IF(AND(I13=0, J13=0), TRUE, FALSE), TRUE) -> TRUE
A14: 46310 | B14: 0.70833333 | C14: C260024 | D14: N | E14: 지인추천 | F14: CS_01 | G14: 진료완료 | H14: 여드름스케일링 | I14: 60000 | J14: 0 | K14: =VLOOKUP($C14,customer_master!$A$2:$F$21,1,0) -> C260024 | L14: =IF(OR(G14="예약취소", G14="노쇼"), I14=0, TRUE) -> TRUE | M14: =IF(OR(G14="예약취소", G14="노쇼"), IF(AND(I14=0, J14=0), TRUE, FALSE), TRUE) -> TRUE
A15: 46310 | B15: 0.72916667 | C15: C260025 | D15: Y | E15: 인스타그램 | F15: CS_02 | G15: 진료완료 | H15: 팔자필러 | I15: 220000 | J15: 0 | K15: =VLOOKUP($C15,customer_master!$A$2:$F$21,1,0) -> C260025 | L15: =IF(OR(G15="예약취소", G15="노쇼"), I15=0, TRUE) -> TRUE | M15: =IF(OR(G15="예약취소", G15="노쇼"), IF(AND(I15=0, J15=0), TRUE, FALSE), TRUE) -> TRUE
A16: 46310 | B16: 0.75 | C16: C260026 | D16: N | E16: 재방문 | F16: CS_03 | G16: 진료완료 | H16: 써마지 600샷 | I16: 0 | J16: 0 | K16: =VLOOKUP($C16,customer_master!$A$2:$F$21,1,0) -> C260026 | L16: =IF(OR(G16="예약취소", G16="노쇼"), I16=0, TRUE) -> TRUE | M16: =IF(OR(G16="예약취소", G16="노쇼"), IF(AND(I16=0, J16=0), TRUE, FALSE), TRUE) -> TRUE
A17: 46311 | B17: 0.41666667 | C17: C260027 | D17: Y | E17: 당근마켓 | F17: CS_01 | G17: 진료완료 | H17: 쥬베룩 볼륨 | I17: 450000 | J17: 0 | K17: =VLOOKUP($C17,customer_master!$A$2:$F$21,1,0) -> C260027 | L17: =IF(OR(G17="예약취소", G17="노쇼"), I17=0, TRUE) -> TRUE | M17: =IF(OR(G17="예약취소", G17="노쇼"), IF(AND(I17=0, J17=0), TRUE, FALSE), TRUE) -> TRUE
A18: 46311 | B18: 0.4375 | C18: C260028 | D18: N | E18: 네이버검색 | F18: CS_02 | G18: 진료완료 | H18: 피코프락셀 | I18: 120000 | J18: 0 | K18: =VLOOKUP($C18,customer_master!$A$2:$F$21,1,0) -> C260028 | L18: =IF(OR(G18="예약취소", G18="노쇼"), I18=0, TRUE) -> TRUE | M18: =IF(OR(G18="예약취소", G18="노쇼"), IF(AND(I18=0, J18=0), TRUE, FALSE), TRUE) -> TRUE
A19: 46311 | B19: 0.46875 | C19: C260029 | D19: Y | E19: 지인추천 | F19: CS_03 | G19: 노쇼 | H19: 종아리보톡스 | I19: 0 | J19: 0 | K19: =VLOOKUP($C19,customer_master!$A$2:$F$21,1,0) -> C260029 | L19: =IF(OR(G19="예약취소", G19="노쇼"), I19=0, TRUE) -> TRUE | M19: =IF(OR(G19="예약취소", G19="노쇼"), IF(AND(I19=0, J19=0), TRUE, FALSE), TRUE) -> TRUE
A20: 46311 | B20: 0.48958333 | C20: C260030 | D20: N | E20: 재방문 | F20: CS_01 | G20: 진료완료 | H20: 애교필러 | I20: 150000 | J20: 0 | K20: =VLOOKUP($C20,customer_master!$A$2:$F$21,1,0) -> C260030 | L20: =IF(OR(G20="예약취소", G20="노쇼"), I20=0, TRUE) -> TRUE | M20: =IF(OR(G20="예약취소", G20="노쇼"), IF(AND(I20=0, J20=0), TRUE, FALSE), TRUE) -> TRUE
A21: 46311 | B21: 0.52083333 | C21: C250011 | D21: Y | E21: 카카오톡 | F21: CS_02 | G21: 진료완료 | H21: 울쎄라 300샷 | I21: 1200000 | J21: 0 | K21: =VLOOKUP($C21,customer_master!$A$2:$F$21,1,0) -> C250011 | L21: =IF(OR(G21="예약취소", G21="노쇼"), I21=0, TRUE) -> TRUE | M21: =IF(OR(G21="예약취소", G21="노쇼"), IF(AND(I21=0, J21=0), TRUE, FALSE), TRUE) -> TRUE
A22: 46311 | B22: 0.58333333 | C22: C250012 | D22: N | E22: 인스타그램 | F22: CS_03 | G22: 예약취소 | H22: 인중제모 | I22: 0 | J22: 0 | K22: =VLOOKUP($C22,customer_master!$A$2:$F$21,1,0) -> C250012 | L22: =IF(OR(G22="예약취소", G22="노쇼"), I22=0, TRUE) -> TRUE | M22: =IF(OR(G22="예약취소", G22="노쇼"), IF(AND(I22=0, J22=0), TRUE, FALSE), TRUE) -> TRUE
A23: 46311 | B23: 0.61111111 | C23: C250013 | D23: Y | E23: 네이버검색 | F23: CS_01 | G23: 진료완료 | H23: 피코토닝 10회 | I23: 850000 | J23: 50000 | K23: =VLOOKUP($C23,customer_master!$A$2:$F$21,1,0) -> C250013 | L23: =IF(OR(G23="예약취소", G23="노쇼"), I23=0, TRUE) -> TRUE | M23: =IF(OR(G23="예약취소", G23="노쇼"), IF(AND(I23=0, J23=0), TRUE, FALSE), TRUE) -> TRUE
A24: 46311 | B24: 0.625 | C24: C250014 | D24: N | E24: 지인추천 | F24: CS_02 | G24: 진료완료 | H24: 사각턱보톡스 | I24: 45000 | J24: 0 | K24: =VLOOKUP($C24,customer_master!$A$2:$F$21,1,0) -> C250014 | L24: =IF(OR(G24="예약취소", G24="노쇼"), I24=0, TRUE) -> TRUE | M24: =IF(OR(G24="예약취소", G24="노쇼"), IF(AND(I24=0, J24=0), TRUE, FALSE), TRUE) -> TRUE
A25: 46311 | B25: 0.63888889 | C25: C250015 | D25: Y | E25: 당근마켓 | F25: CS_03 | G25: 진료완료 | H25: 입술필러 | I25: 200000 | J25: 0 | K25: =VLOOKUP($C25,customer_master!$A$2:$F$21,1,0) -> C250015 | L25: =IF(OR(G25="예약취소", G25="노쇼"), I25=0, TRUE) -> TRUE | M25: =IF(OR(G25="예약취소", G25="노쇼"), IF(AND(I25=0, J25=0), TRUE, FALSE), TRUE) -> TRUE | N25: 잔금 수정
A26: 46311 | B26: 0.66666667 | C26: C250016 | D26: N | E26: 카카오톡 | F26: CS_01 | G26: 진료완료 | H26: 인모드 FX | I26: 120000 | J26: 0 | K26: =VLOOKUP($C26,customer_master!$A$2:$F$21,1,0) -> C250016 | L26: =IF(OR(G26="예약취소", G26="노쇼"), I26=0, TRUE) -> TRUE | M26: =IF(OR(G26="예약취소", G26="노쇼"), IF(AND(I26=0, J26=0), TRUE, FALSE), TRUE) -> TRUE
A27: 46311 | B27: 0.6875 | C27: C250017 | D27: Y | E27: 재방문 | F27: CS_02 | G27: 예약취소 | H27: 리쥬란힐러 2cc | I27: 0 | J27: 0 | K27: =VLOOKUP($C27,customer_master!$A$2:$F$21,1,0) -> C250017 | L27: =IF(OR(G27="예약취소", G27="노쇼"), I27=0, TRUE) -> TRUE | M27: =IF(OR(G27="예약취소", G27="노쇼"), IF(AND(I27=0, J27=0), TRUE, FALSE), TRUE) -> TRUE | N27: 잔금삭제
A28: 46311 | B28: 0.70833333 | C28: C250018 | D28: N | E28: 네이버검색 | F28: CS_03 | G28: 노쇼 | H28: 겨드랑이제모 5회 | I28: 0 | J28: 0 | K28: =VLOOKUP($C28,customer_master!$A$2:$F$21,1,0) -> C250018 | L28: =IF(OR(G28="예약취소", G28="노쇼"), I28=0, TRUE) -> TRUE | M28: =IF(OR(G28="예약취소", G28="노쇼"), IF(AND(I28=0, J28=0), TRUE, FALSE), TRUE) -> TRUE
A29: 46311 | B29: 0.73611111 | C29: C250019 | D29: Y | E29: 지인추천 | F29: CS_01 | G29: 진료완료 | H29: 피코프락셀 | I29: 120000 | J29: 0 | K29: =VLOOKUP($C29,customer_master!$A$2:$F$21,1,0) -> C250019 | L29: =IF(OR(G29="예약취소", G29="노쇼"), I29=0, TRUE) -> TRUE | M29: =IF(OR(G29="예약취소", G29="노쇼"), IF(AND(I29=0, J29=0), TRUE, FALSE), TRUE) -> TRUE
A30: 46312 | B30: 0.41666667 | C30: C250020 | D30: N | E30: 인스타그램 | F30: CS_02 | G30: 진료완료 | H30: 미간보톡스 | I30: 35000 | J30: 0 | K30: =VLOOKUP($C30,customer_master!$A$2:$F$21,1,0) -> C250020 | L30: =IF(OR(G30="예약취소", G30="노쇼"), I30=0, TRUE) -> TRUE | M30: =IF(OR(G30="예약취소", G30="노쇼"), IF(AND(I30=0, J30=0), TRUE, FALSE), TRUE) -> TRUE
A31: 46312 | B31: 0.42708333 | C31: C260021 | D31: Y | E31: 카카오톡 | F31: CS_03 | G31: 진료완료 | H31: 코필러 | I31: 180000 | J31: 50000 | K31: =VLOOKUP($C31,customer_master!$A$2:$F$21,1,0) -> C260021 | L31: =IF(OR(G31="예약취소", G31="노쇼"), I31=0, TRUE) -> TRUE | M31: =IF(OR(G31="예약취소", G31="노쇼"), IF(AND(I31=0, J31=0), TRUE, FALSE), TRUE) -> TRUE
A32: 46312 | B32: 0.45833333 | C32: C260022 | D32: N | E32: 재방문 | F32: CS_01 | G32: 진료완료 | H32: 울쎄라 600샷 | I32: 2200000 | J32: 0 | K32: =VLOOKUP($C32,customer_master!$A$2:$F$21,1,0) -> C260022 | L32: =IF(OR(G32="예약취소", G32="노쇼"), I32=0, TRUE) -> TRUE | M32: =IF(OR(G32="예약취소", G32="노쇼"), IF(AND(I32=0, J32=0), TRUE, FALSE), TRUE) -> TRUE
A33: 46312 | B33: 0.47916667 | C33: C260023 | D33: Y | E33: 네이버검색 | F33: CS_02 | G33: 예약취소 | H33: 슈링크 400샷 | I33: 0 | J33: 0 | K33: =VLOOKUP($C33,customer_master!$A$2:$F$21,1,0) -> C260023 | L33: =IF(OR(G33="예약취소", G33="노쇼"), I33=0, TRUE) -> TRUE | M33: =IF(OR(G33="예약취소", G33="노쇼"), IF(AND(I33=0, J33=0), TRUE, FALSE), TRUE) -> TRUE
A34: 46312 | B34: 0.5 | C34: C260024 | D34: N | E34: 지인추천 | F34: CS_03 | G34: 진료완료 | H34: 종아리제모 | I34: 80000 | J34: 0 | K34: =VLOOKUP($C34,customer_master!$A$2:$F$21,1,0) -> C260024 | L34: =IF(OR(G34="예약취소", G34="노쇼"), I34=0, TRUE) -> TRUE | M34: =IF(OR(G34="예약취소", G34="노쇼"), IF(AND(I34=0, J34=0), TRUE, FALSE), TRUE) -> TRUE
A35: 46312 | B35: 0.54166667 | C35: C260025 | D35: Y | E35: 당근마켓 | F35: CS_01 | G35: 노쇼 | H35: 피코토닝 10회 | I35: 0 | J35: 0 | K35: =VLOOKUP($C35,customer_master!$A$2:$F$21,1,0) -> C260025 | L35: =IF(OR(G35="예약취소", G35="노쇼"), I35=0, TRUE) -> TRUE | M35: =IF(OR(G35="예약취소", G35="노쇼"), IF(AND(I35=0, J35=0), TRUE, FALSE), TRUE) -> TRUE
A36: 46312 | B36: 0.5625 | C36: C260026 | D36: N | E36: 카카오톡 | F36: CS_02 | G36: 진료완료 | H36: 사각턱보톡스 | I36: 45000 | J36: 0 | K36: =VLOOKUP($C36,customer_master!$A$2:$F$21,1,0) -> C260026 | L36: =IF(OR(G36="예약취소", G36="노쇼"), I36=0, TRUE) -> TRUE | M36: =IF(OR(G36="예약취소", G36="노쇼"), IF(AND(I36=0, J36=0), TRUE, FALSE), TRUE) -> TRUE
A37: 46312 | B37: 0.58333333 | C37: C260027 | D37: Y | E37: 재방문 | F37: CS_03 | G37: 진료완료 | H37: 팔자필러 | I37: 220000 | J37: 0 | K37: =VLOOKUP($C37,customer_master!$A$2:$F$21,1,0) -> C260027 | L37: =IF(OR(G37="예약취소", G37="노쇼"), I37=0, TRUE) -> TRUE | M37: =IF(OR(G37="예약취소", G37="노쇼"), IF(AND(I37=0, J37=0), TRUE, FALSE), TRUE) -> TRUE
A38: 46312 | B38: 0.61458333 | C38: C260028 | D38: N | E38: 인스타그램 | F38: CS_01 | G38: 진료완료 | H38: 써마지 600샷 | I38: 2500000 | J38: 500000 | K38: =VLOOKUP($C38,customer_master!$A$2:$F$21,1,0) -> C260028 | L38: =IF(OR(G38="예약취소", G38="노쇼"), I38=0, TRUE) -> TRUE | M38: =IF(OR(G38="예약취소", G38="노쇼"), IF(AND(I38=0, J38=0), TRUE, FALSE), TRUE) -> TRUE
A39: 46312 | B39: 0.63541667 | C39: C260029 | D39: Y | E39: 지인추천 | F39: CS_02 | G39: 진료완료 | H39: 쥬베룩 볼륨 | I39: 450000 | J39: 0 | K39: =VLOOKUP($C39,customer_master!$A$2:$F$21,1,0) -> C260029 | L39: =IF(OR(G39="예약취소", G39="노쇼"), I39=0, TRUE) -> TRUE | M39: =IF(OR(G39="예약취소", G39="노쇼"), IF(AND(I39=0, J39=0), TRUE, FALSE), TRUE) -> TRUE
A40: 46312 | B40: 0.66666667 | C40: C250011 | D40: Y | E40: 카카오톡 | F40: CS_01 | G40: 진료완료 | H40: 피코프락셀 | I40: 120000 | J40: 0 | K40: =VLOOKUP($C40,customer_master!$A$2:$F$21,1,0) -> C250011 | L40: =IF(OR(G40="예약취소", G40="노쇼"), I40=0, TRUE) -> TRUE | M40: =IF(OR(G40="예약취소", G40="노쇼"), IF(AND(I40=0, J40=0), TRUE, FALSE), TRUE) -> TRUE
...

Sheet 일일매출지표
B2: 📅 일일 핵심 KPI 대시보드 (2026-10-15 ~ 10-18)
B4: 총 수납금액 (원) | D4: 총 미수 잔금 (원) | G4: 신규 환자(신환) 유입 수 | I4: 총 진료 완료 건수
B5: =SUM(RAW_DATA!$I$2:$I$48) -> 13804000 | D5: =SUM(RAW_DATA!$J$2:$J$48) -> 900000 | G5: =COUNTIFS(RAW_DATA!$D$2:$D$48, "Y", RAW_DATA!$G$2:$G$48, "진료완료") -> 15 | I5: =COUNTIF(RAW_DATA!$G$2:$G$48,"진료완료") -> 34
B8: 📌 유입경로별 매출 및 잔금 현황 | I8: 📌 날짜별 마감 실적
B10: 유입 경로 | C10: 예약 건수 | D10: 노쇼 건수 | E10: 예약취소 건수 | F10: 실제 수납금액(원) | G10: 미수 잔금(원) | I10: 예약일자 | J10: 당일 예약 건수 | K10: 당일 수납금액(원) | L10: 당일 잔금(원)
B11: 네이버검색 | C11: =COUNTIFS(RAW_DATA!$E$2:$E$48,B11,RAW_DATA!$G$2:$G$48,"진료완료") -> 3 | D11: =COUNTIFS(RAW_DATA!$E$2:$E$48,B11,RAW_DATA!$G$2:$G$48,"노쇼") -> 2 | E11: =COUNTIFS(RAW_DATA!$E$2:$E$48,B11,RAW_DATA!$G$2:$G$48,"예약취소") -> 2 | F11: =SUMIF(RAW_DATA!$E$2:$E$48, B11, RAW_DATA!$I$2:$I$48) -> 1260000 | G11: =SUMIF(RAW_DATA!$E$2:$E$48, $B11, RAW_DATA!$J$2:$J$48) -> 50000 | I11: 2026-10-15 | J11: =COUNTIFS(RAW_DATA!$A$2:$A$48,일일매출지표!$I11,RAW_DATA!$G$2:$G$48,"진료완료") -> 11 | K11: =SUMIF(RAW_DATA!$A$2:$A$48,일일매출지표!$I11,RAW_DATA!$I$2:$I$48) -> 2934000 | L11: =SUMIF(RAW_DATA!$A$2:$A$48,일일매출지표!$I11,RAW_DATA!$J$2:$J$48) -> 300000
B12: 인스타그램 | C12: =COUNTIFS(RAW_DATA!$E$2:$E$48,B12,RAW_DATA!$G$2:$G$48,"진료완료") -> 5 | D12: =COUNTIFS(RAW_DATA!$E$2:$E$48,B12,RAW_DATA!$G$2:$G$48,"노쇼") -> 1 | E12: =COUNTIFS(RAW_DATA!$E$2:$E$48,B12,RAW_DATA!$G$2:$G$48,"예약취소") -> 1 | F12: =SUMIF(RAW_DATA!$E$2:$E$48, B12, RAW_DATA!$I$2:$I$48) -> 4245000 | G12: =SUMIF(RAW_DATA!$E$2:$E$48, $B12, RAW_DATA!$J$2:$J$48) -> 800000 | I12: 2026-10-16 | J12: =COUNTIFS(RAW_DATA!$A$2:$A$48,일일매출지표!$I12,RAW_DATA!$G$2:$G$48,"진료완료") -> 9 | K12: =SUMIF(RAW_DATA!$A$2:$A$48,일일매출지표!$I12,RAW_DATA!$I$2:$I$48) -> 3255000 | L12: =SUMIF(RAW_DATA!$A$2:$A$48,일일매출지표!$I12,RAW_DATA!$J$2:$J$48) -> 50000
B13: 카카오톡 | C13: =COUNTIFS(RAW_DATA!$E$2:$E$48,B13,RAW_DATA!$G$2:$G$48,"진료완료") -> 9 | D13: =COUNTIFS(RAW_DATA!$E$2:$E$48,B13,RAW_DATA!$G$2:$G$48,"노쇼") -> 0 | E13: =COUNTIFS(RAW_DATA!$E$2:$E$48,B13,RAW_DATA!$G$2:$G$48,"예약취소") -> 0 | F13: =SUMIF(RAW_DATA!$E$2:$E$48, B13, RAW_DATA!$I$2:$I$48) -> 2645000 | G13: =SUMIF(RAW_DATA!$E$2:$E$48, $B13, RAW_DATA!$J$2:$J$48) -> 50000 | I13: 2026-10-17 | J13: =COUNTIFS(RAW_DATA!$A$2:$A$48,일일매출지표!$I13,RAW_DATA!$G$2:$G$48,"진료완료") -> 12 | K13: =SUMIF(RAW_DATA!$A$2:$A$48,일일매출지표!$I13,RAW_DATA!$I$2:$I$48) -> 7520000 | L13: =SUMIF(RAW_DATA!$A$2:$A$48,일일매출지표!$I13,RAW_DATA!$J$2:$J$48) -> 550000
B14: 당근마켓 | C14: =COUNTIFS(RAW_DATA!$E$2:$E$48,B14,RAW_DATA!$G$2:$G$48,"진료완료") -> 3 | D14: =COUNTIFS(RAW_DATA!$E$2:$E$48,B14,RAW_DATA!$G$2:$G$48,"노쇼") -> 1 | E14: =COUNTIFS(RAW_DATA!$E$2:$E$48,B14,RAW_DATA!$G$2:$G$48,"예약취소") -> 1 | F14: =SUMIF(RAW_DATA!$E$2:$E$48, B14, RAW_DATA!$I$2:$I$48) -> 850000 | G14: =SUMIF(RAW_DATA!$E$2:$E$48, $B14, RAW_DATA!$J$2:$J$48) -> 0 | I14: 2026-10-18 | J14: =COUNTIFS(RAW_DATA!$A$2:$A$48,일일매출지표!$I14,RAW_DATA!$G$2:$G$48,"진료완료") -> 2 | K14: =SUMIF(RAW_DATA!$A$2:$A$48,일일매출지표!$I14,RAW_DATA!$I$2:$I$48) -> 95000 | L14: =SUMIF(RAW_DATA!$A$2:$A$48,일일매출지표!$I14,RAW_DATA!$J$2:$J$48) -> 0
B15: 지인추천 | C15: =COUNTIFS(RAW_DATA!$E$2:$E$48,B15,RAW_DATA!$G$2:$G$48,"진료완료") -> 7 | D15: =COUNTIFS(RAW_DATA!$E$2:$E$48,B15,RAW_DATA!$G$2:$G$48,"노쇼") -> 2 | E15: =COUNTIFS(RAW_DATA!$E$2:$E$48,B15,RAW_DATA!$G$2:$G$48,"예약취소") -> 0 | F15: =SUMIF(RAW_DATA!$E$2:$E$48, B15, RAW_DATA!$I$2:$I$48) -> 2105000 | G15: =SUMIF(RAW_DATA!$E$2:$E$48, $B15, RAW_DATA!$J$2:$J$48) -> 0 | I15: 합계 | J15: =SUM($J$11:$J$14) -> 34 | K15: =SUM($K$11:$K$14) -> 13804000 | L15: =SUM($L$11:$L$14) -> 900000
B16: 재방문 | C16: =COUNTIFS(RAW_DATA!$E$2:$E$48,B16,RAW_DATA!$G$2:$G$48,"진료완료") -> 7 | D16: =COUNTIFS(RAW_DATA!$E$2:$E$48,B16,RAW_DATA!$G$2:$G$48,"노쇼") -> 1 | E16: =COUNTIFS(RAW_DATA!$E$2:$E$48,B16,RAW_DATA!$G$2:$G$48,"예약취소") -> 2 | F16: =SUMIF(RAW_DATA!$E$2:$E$48, B16, RAW_DATA!$I$2:$I$48) -> 2699000 | G16: =SUMIF(RAW_DATA!$E$2:$E$48, $B16, RAW_DATA!$J$2:$J$48) -> 0
B17: 합계 | C17: =SUM($C$11:$C$16) -> 34 | D17: =SUM($D$11:$D$16) -> 7 | E17: =SUM($E$11:$E$16) -> 6 | F17: =SUM($F$11:$F$16) -> 13804000 | G17: =SUM($G$11:$G$16) -> 900000
B18: 총건수 | C18: =SUM($C$17:$E$17) -> 47 | F18: =SUM($F$17:$G$17) -> 14704000
