Workbook

Sheet 프로젝트개요
A1: 🏥 [프로젝트 개요] 의료 MSO 비즈니스 데이터 파이프라인 및 CRM Data QA
A3: 목적: 예약 및 결제 트랜잭션의 정합성 검증(Data QA)을 통해 이상치를 제거하고, 신뢰도 높은 일일 경영 KPI 대시보드 구축
A5: 기술 스택: SQL (HeidiSQL, MySQL) | Excel (다중 논리함수, VLOOKUP) | Google Sheets
A7: 📊 [일일매출지표 대시보드 바로가기]
A9: 깃허브 저장소(SQL 쿼리 및 소스코드 원본)
A11: 🔍 핵심 데이터 정합성 검증 (Data QA 내역 - 총 9건 오류 정제)
A13: 1. 기준정보 누락 검증 (VLOOKUP): 회원 마스터에 미등록된 이상 차트번호 3건 탐지 및 정제
A15: 2. 비즈니스 로직 모순 검증 (IF/OR/AND): 예약 취소/노쇼 상태임에도 결제액·잔금이 잔존하는 데이터 5건 탐지 ➔ 0원 보정
A17: 3. 수납 이상치 검증: 잔금이 음수(-20,000원)로 오입력된 수납 기입 오류 1건 탐지 ➔ 정상화 조치
A19: 📊 일일 핵심 경영 KPI 요약 (2026-10-15 ~ 2026-10-18) • 총 수납금액: 13,804,000원 (총 34건 진료 완료 기준) • 총 미수 잔금: 900,000원 • 총 예약 건수: 47건 (진료 완료 34건, 노쇼 7건, 예약 취소 6건) • 신규 환자(신환) 유입: 15건 (전체 완료 건수 34건 중 신환 15건, 구환 19건) 💡 핵심 분석 인사이트 및 전략적 제언 (Key Takeaways) 1. 인스타그램 채널의 고매출 견인 및 미수 잔금 리스크 관리 필요 • 매출 기여도 1위: '유입 채널별 수납금액 및 미수 잔금 현황' 차트에서 볼 수 있듯이, 인스타그램 유입은 총 7건의 예약 중 5건이 진료 완료되어 4,245,000원(전체 수납액의 30.8%)을 기록한 최고 매출 채널입니다. • 미수금 리스크 집중: 전체 미수 잔금(900,000원) 중 **88.9%(800,000원)**가 인스타그램 유입 환자에 집중되어 있습니다. • 주요 미수 사례: 차트번호 C250014(울쎄라 300샷, 잔금 300,000원), C260028(써마지 600샷, 잔금 500,000원) • 고단가 시술 편중: 울쎄라, 써마지 등 고단가 프리미엄 리프팅 시술 수요가 인스타그램 채널에 집중되는 경향을 보입니다. • 실행 제언: 고단가 시술 예약 시 사전 예약금(Deposit) 결제 프로토콜을 도입하고, 시술 당일 수납 완납을 원칙으로 설정하여 미수금 발생을 선제적으로 차단해야 합니다.
A20: 2. 카카오톡 채널의 뛰어난 진료 이행도와 고객 락인(Lock-in) 효과 • 이탈률 0% (완수율 100%): 카카오톡 유입은 총 9건의 예약 중 노쇼나 예약 취소가 단 1건도 발생하지 않고 전건(9건) 진료 완료되었습니다. • 안정적인 수납 무결성: 총 2,645,000원(전체 매출의 19.2%)의 매출을 올렸으며, 미수 잔금은 50,000원에 불과해 가장 안정적인 수납 흐름을 보여줍니다. • 대표 완료 건: C250011(피코토닝 10회, 850,000원), C260023(피코토닝 10회, 850,000원) 등 9건 • 실행 제언: 진료 이행도와 신뢰도가 검증된 카카오톡 유입 고객을 대상으로 주기적 재방문 리텐션 알림 및 지인 추천 프로모션을 연계하여 충성 고객층으로 확고히 락인할 것을 권장합니다. 3. 네이버검색 및 당근마켓 채널의 높은 이탈률 개선과 스케줄링 최적화 • 높은 노쇼 및 취소율: 네이버검색 유입은 총 7건 중 4건(노쇼 2건, 취소 2건, 이탈률 57.1%), 당근마켓 유입은 총 5건 중 2건(노쇼 1건, 취소 1건, 이탈률 40.0%)의 이탈이 발생했습니다. • 진료 공백 발생: 이 두 채널에서 발생한 6건의 이탈은 전체 노쇼/취소(13건)의 **46.2%**를 차지하여 병원 원장단 및 상담원의 운영 리소스 손실을 초과 발생시키고 있습니다. • 실행 제언: 예약 전일/당일 카카오 알림톡 자동 확인 시스템을 의무화하고, 노쇼 발생 가능성이 높은 채널은 당일 대기 환자를 순서대로 배정하는 가변 스케줄링을 도입할 필요가 있습니다. 📈 매출 추이 및 시술 항목별 분석 • 일자별 매출 추이: '일자별 매출 추이 (2026-10-15 ~ 10-18)' 차트에 나타나듯, 10월 17일에 수납금액 7,520,000원(진료 완료 12건)으로 주말 전 최고 매출을 달성했습니다. • 10월 15일: 2,934,000원 (11건 완료) • 10월 16일: 3,255,000원 (9건 완료) • 10월 17일: 7,520,000원 (12건 완료) • 10월 18일: 95,000원 (2건 완료) • 주요 시술 항목별 매출 TOP 5: '주요 시술 항목별 매출 TOP 5' 차트 기준으로 고단가 리프팅 및 피부 개선 시술이 전체 매출을 선도하고 있습니다. 1. 울쎄라 300샷: 3,600,000원 (3건 완료 - C250014, C260027, C260030) 2. 써마지 600샷: 2,500,000원 (2건 완료 - C260028, C260029) 3. 울쎄라 600샷: 2,200,000원 (1건 완료 - C250020) 4. 피코토닝 10회: 1,700,000원 (2건 완료 - C250011, C260023) 5. 쥬베룩 볼륨: 900,000원 (2건 완료 - C260024, C260025)

Sheet 일일매출지표
B2: 📅 일일 핵심 KPI 대시보드 (2026-10-15 ~ 10-18)
B4: 총 수납금액 (원) | D4: 총 미수 잔금 (원) | G4: 신규 환자(신환) 유입 수 | I4: 총 진료 완료 건수
B5: =SUM(RAW_DATA!$I$2:$I$48) -> 13804000 | D5: =SUM(RAW_DATA!$J$2:$J$48) -> 900000 | G5: =COUNTIFS(RAW_DATA!$D$2:$D$48, "Y", RAW_DATA!$G$2:$G$48, "진료완료") -> 15 | I5: =COUNTIF(RAW_DATA!$G$2:$G$48,"진료완료") -> 34
B8: 📌 유입경로별 매출 및 잔금 현황 | I8: 📌 날짜별 마감 실적
B10: 유입 경로 | C10: 예약 건수 | D10: 노쇼 건수 | E10: 예약취소 건수 | F10: 실제 수납금액(원) | G10: 미수 잔금(원) | I10: 예약일자 | J10: 당일 예약 건수 | K10: 당일 수납금액(원) | L10: 당일 잔금(원)
B11: 네이버검색 | C11: =COUNTIFS(RAW_DATA!$E$2:$E$48,B11,RAW_DATA!$G$2:$G$48,"진료완료") -> 3 | D11: =COUNTIFS(RAW_DATA!$E$2:$E$48,B11,RAW_DATA!$G$2:$G$48,"노쇼") -> 2 | E11: =COUNTIFS(RAW_DATA!$E$2:$E$48,B11,RAW_DATA!$G$2:$G$48,"예약취소") -> 2 | F11: =SUMIF(RAW_DATA!$E$2:$E$48, B11, RAW_DATA!$I$2:$I$48) -> 1260000 | G11: =SUMIF(RAW_DATA!$E$2:$E$48, $B11, RAW_DATA!$J$2:$J$48) -> 50000 | I11: 2026-10-15 | J11: =COUNTIFS(RAW_DATA!$A$2:$A$48,일일매출지표!$I11,RAW_DATA!$G$2:$G$48,"진료완료") -> 11 | K11: =SUMIF(RAW_DATA!$A$2:$A$48,일일매출지표!$I11,RAW_DATA!$I$2:$I$48) -> 2934000 | L11: =SUMIF(RAW_DATA!$A$2:$A$48,일일매출지표!$I11,RAW_DATA!$J$2:$J$48) -> 300000
B12: 인스타그램 | C12: =COUNTIFS(RAW_DATA!$E$2:$E$48,B12,RAW_DATA!$G$2:$G$48,"진료완료") -> 5 | D12: =COUNTIFS(RAW_DATA!$E$2:$E$48,B12,RAW_DATA!$G$2:$G$48,"노쇼") -> 1 | E12: =COUNTIFS(RAW_DATA!$E$2:$E$48,B12,RAW_DATA!$G$2:$G$48,"예약취소") -> 1 | F12: =SUMIF(RAW_DATA!$E$2:$E$48, B12, RAW_DATA!$I$2:$I$48) -> 4245000 | G12: =SUMIF(RAW_DATA!$E$2:$E$48, $B12, RAW_DATA!$J$2:$J$48) -> 800000 | I12: 2026-10-16 | J12: =COUNTIFS(RAW_DATA!$A$2:$A$48,일일매출지표!$I12,RAW_DATA!$G$2:$G$48,"진료완료") -> 9 | K12: =SUMIF(RAW_DATA!$A$2:$A$48,일일매출지표!$I12,RAW_DATA!$I$2:$I$48) -> 3255000 | L12: =SUMIF(RAW_DATA!$A$2:$A$48,일일매출지표!$I12,RAW_DATA!$J$2:$J$48) -> 50000
B13: 카카오톡 | C13: =COUNTIFS(RAW_DATA!$E$2:$E$48,B13,RAW_DATA!$G$2:$G$48,"진료완료") -> 9 | D13: =COUNTIFS(RAW_DATA!$E$2:$E$48,B13,RAW_DATA!$G$2:$G$48,"노쇼") -> 0 | E13: =COUNTIFS(RAW_DATA!$E$2:$E$48,B13,RAW_DATA!$G$2:$G$48,"예약취소") -> 0 | F13: =SUMIF(RAW_DATA!$E$2:$E$48, B13, RAW_DATA!$I$2:$I$48) -> 2645000 | G13: =SUMIF(RAW_DATA!$E$2:$E$48, $B13, RAW_DATA!$J$2:$J$48) -> 50000 | I13: 2026-10-17 | J13: =COUNTIFS(RAW_DATA!$A$2:$A$48,일일매출지표!$I13,RAW_DATA!$G$2:$G$48,"진료완료") -> 12 | K13: =SUMIF(RAW_DATA!$A$2:$A$48,일일매출지표!$I13,RAW_DATA!$I$2:$I$48) -> 7520000 | L13: =SUMIF(RAW_DATA!$A$2:$A$48,일일매출지표!$I13,RAW_DATA!$J$2:$J$48) -> 550000
B14: 당근마켓 | C14: =COUNTIFS(RAW_DATA!$E$2:$E$48,B14,RAW_DATA!$G$2:$G$48,"진료완료") -> 3 | D14: =COUNTIFS(RAW_DATA!$E$2:$E$48,B14,RAW_DATA!$G$2:$G$48,"노쇼") -> 1 | E14: =COUNTIFS(RAW_DATA!$E$2:$E$48,B14,RAW_DATA!$G$2:$G$48,"예약취소") -> 1 | F14: =SUMIF(RAW_DATA!$E$2:$E$48, B14, RAW_DATA!$I$2:$I$48) -> 850000 | G14: =SUMIF(RAW_DATA!$E$2:$E$48, $B14, RAW_DATA!$J$2:$J$48) -> 0 | I14: 2026-10-18 | J14: =COUNTIFS(RAW_DATA!$A$2:$A$48,일일매출지표!$I14,RAW_DATA!$G$2:$G$48,"진료완료") -> 2 | K14: =SUMIF(RAW_DATA!$A$2:$A$48,일일매출지표!$I14,RAW_DATA!$I$2:$I$48) -> 95000 | L14: =SUMIF(RAW_DATA!$A$2:$A$48,일일매출지표!$I14,RAW_DATA!$J$2:$J$48) -> 0
B15: 지인추천 | C15: =COUNTIFS(RAW_DATA!$E$2:$E$48,B15,RAW_DATA!$G$2:$G$48,"진료완료") -> 7 | D15: =COUNTIFS(RAW_DATA!$E$2:$E$48,B15,RAW_DATA!$G$2:$G$48,"노쇼") -> 2 | E15: =COUNTIFS(RAW_DATA!$E$2:$E$48,B15,RAW_DATA!$G$2:$G$48,"예약취소") -> 0 | F15: =SUMIF(RAW_DATA!$E$2:$E$48, B15, RAW_DATA!$I$2:$I$48) -> 2105000 | G15: =SUMIF(RAW_DATA!$E$2:$E$48, $B15, RAW_DATA!$J$2:$J$48) -> 0 | I15: 합계 | J15: =SUM($J$11:$J$14) -> 34 | K15: =SUM($K$11:$K$14) -> 13804000 | L15: =SUM($L$11:$L$14) -> 900000
B16: 재방문 | C16: =COUNTIFS(RAW_DATA!$E$2:$E$48,B16,RAW_DATA!$G$2:$G$48,"진료완료") -> 7 | D16: =COUNTIFS(RAW_DATA!$E$2:$E$48,B16,RAW_DATA!$G$2:$G$48,"노쇼") -> 1 | E16: =COUNTIFS(RAW_DATA!$E$2:$E$48,B16,RAW_DATA!$G$2:$G$48,"예약취소") -> 2 | F16: =SUMIF(RAW_DATA!$E$2:$E$48, B16, RAW_DATA!$I$2:$I$48) -> 2699000 | G16: =SUMIF(RAW_DATA!$E$2:$E$48, $B16, RAW_DATA!$J$2:$J$48) -> 0
B17: 합계 | C17: =SUM($C$11:$C$16) -> 34 | D17: =SUM($D$11:$D$16) -> 7 | E17: =SUM($E$11:$E$16) -> 6 | F17: =SUM($F$11:$F$16) -> 13804000 | G17: =SUM($G$11:$G$16) -> 900000
B18: 총건수 | C18: =SUM($C$17:$E$17) -> 47 | F18: =SUM($F$17:$G$17) -> 14704000
B36: Treatment_Item | C36: 수납금액 | E36: Reservation_Date | F36: 수납금액 | H36: Inflow_Channel | I36: 수납금액 | J36: 미수잔금
B37: 써마지 600샷 | C37: =SUMIF(RAW_DATA!$H$2:$H$48,일일매출지표!$B37,RAW_DATA!$I$2:$I$48) -> 2500000 | E37: 46310 | F37: ` | H37: 네이버검색 | I37: =SUMIF(RAW_DATA!$E$2:$E$48, H37, RAW_DATA!$I$2:$I$48) -> 1260000 | J37: =SUMIF(RAW_DATA!$E$2:$E$48, H36, RAW_DATA!$J$2:$J$48) -> 0
B38: 울쎄라 300샷 | C38: =SUMIF(RAW_DATA!$H$2:$H$48,일일매출지표!$B38,RAW_DATA!$I$2:$I$48) -> 3600000 | E38: 46311 | F38: =SUMIF(RAW_DATA!$A$2:$A$48,일일매출지표!$E38,RAW_DATA!$I$2:$I$48) -> 3255000 | H38: 당근마켓 | I38: =SUMIF(RAW_DATA!$E$2:$E$48, H38, RAW_DATA!$I$2:$I$48) -> 850000 | J38: =SUMIF(RAW_DATA!$E$2:$E$48, H37, RAW_DATA!$J$2:$J$48) -> 50000
B39: 울쎄라 600샷 | C39: =SUMIF(RAW_DATA!$H$2:$H$48,일일매출지표!$B39,RAW_DATA!$I$2:$I$48) -> 2200000 | E39: 46312 | F39: =SUMIF(RAW_DATA!$A$2:$A$48,일일매출지표!$E39,RAW_DATA!$I$2:$I$48) -> 7520000 | H39: 인스타그램 | I39: =SUMIF(RAW_DATA!$E$2:$E$48, H39, RAW_DATA!$I$2:$I$48) -> 4245000 | J39: =SUMIF(RAW_DATA!$E$2:$E$48, H38, RAW_DATA!$J$2:$J$48) -> 0
B40: 쥬베룩 볼륨 | C40: =SUMIF(RAW_DATA!$H$2:$H$48,일일매출지표!$B40,RAW_DATA!$I$2:$I$48) -> 900000 | E40: 46313 | F40: =SUMIF(RAW_DATA!$A$2:$A$48,일일매출지표!$E40,RAW_DATA!$I$2:$I$48) -> 95000 | H40: 재방문 | I40: =SUMIF(RAW_DATA!$E$2:$E$48, H40, RAW_DATA!$I$2:$I$48) -> 2699000 | J40: =SUMIF(RAW_DATA!$E$2:$E$48, H39, RAW_DATA!$J$2:$J$48) -> 800000
B41: 피코토닝 10회 | C41: =SUMIF(RAW_DATA!$H$2:$H$48,일일매출지표!$B41,RAW_DATA!$I$2:$I$48) -> 1700000 | H41: 지인추천 | I41: =SUMIF(RAW_DATA!$E$2:$E$48, H41, RAW_DATA!$I$2:$I$48) -> 2105000 | J41: =SUMIF(RAW_DATA!$E$2:$E$48, H40, RAW_DATA!$J$2:$J$48) -> 0
H42: 카카오톡 | I42: =SUMIF(RAW_DATA!$E$2:$E$48, H42, RAW_DATA!$I$2:$I$48) -> 2645000 | J42: =SUMIF(RAW_DATA!$E$2:$E$48, H41, RAW_DATA!$J$2:$J$48) -> 0

Sheet 신환구환_심화분석
A1: 🏥 신환(신규) vs 구환(재방문) 심화 분석 대시보드
A2: 의료 MSO 마케팅 채널 효율성 및 환자 유형별 진료 매출·이탈율 심층 분석
A4: 주요 지표 | B4: 총 예약 건수 | C4: =COUNTA(RAW_DATA!A2:A48) -> 47 | D4: 신환 예약 건수 | E4: =COUNTIF(RAW_DATA!D2:D48, "Y") -> 22 | F4: 신환 비율 | G4: =E4/C4 -> 0.46808511 | H4: 신환 수납금액 | I4: =SUMIF(RAW_DATA!D2:D48, "Y", RAW_DATA!I2:I48) -> 4885000
A5: KPI 요약 | B5: 진료 완료 건수 | C5: =COUNTIF(RAW_DATA!G2:G48, "진료완료") -> 34 | D5: 구환 예약 건수 | E5: =COUNTIF(RAW_DATA!D2:D48, "N") -> 25 | F5: 구환 비율 | G5: =E5/C4 -> 0.53191489 | H5: 구환 수납금액 | I5: =SUMIF(RAW_DATA!D2:D48, "N", RAW_DATA!I2:I48) -> 8919000
A8: 📊 [분석 1] 유입 채널별 신환 vs 구환 예약 및 매출 기여도
A9: 유입 채널 | B9: 전체 예약 | C9: 신환 건수(Y) | D9: 구환 건수(N) | E9: 신환 비중 | F9: 진료완료 건수 | G9: 진료완료율 | H9: 총 수납금액(원) | I9: 신환 수납액(원) | J9: 구환 수납액(원) | K9: 신환 매출비중
A10: 인스타그램 | B10: =COUNTIF(RAW_DATA!$E$2:$E$48, A10) -> 7 | C10: =COUNTIFS(RAW_DATA!$E$2:$E$48, A10, RAW_DATA!$D$2:$D$48, "Y") -> 2 | D10: =COUNTIFS(RAW_DATA!$E$2:$E$48, A10, RAW_DATA!$D$2:$D$48, "N") -> 5 | E10: =IFERROR(C10/B10, 0) -> 0.28571429 | F10: =COUNTIFS(RAW_DATA!$E$2:$E$48, A10, RAW_DATA!$G$2:$G$48, "진료완료") -> 5 | G10: =IFERROR(F10/B10, 0) -> 0.71428571 | H10: =SUMIFS(RAW_DATA!$I$2:$I$48, RAW_DATA!$E$2:$E$48, A10, RAW_DATA!$G$2:$G$48, "진료완료") -> 4245000 | I10: =SUMIFS(RAW_DATA!$I$2:$I$48, RAW_DATA!$E$2:$E$48, A10, RAW_DATA!$D$2:$D$48, "Y", RAW_DATA!$G$2:$G$48, "진료완료") -> 510000 | J10: =SUMIFS(RAW_DATA!$I$2:$I$48, RAW_DATA!$E$2:$E$48, A10, RAW_DATA!$D$2:$D$48, "N", RAW_DATA!$G$2:$G$48, "진료완료") -> 3735000 | K10: =IFERROR(I10/H10, 0) -> 0.12014134
A11: 카카오톡 | B11: =COUNTIF(RAW_DATA!$E$2:$E$48, A11) -> 9 | C11: =COUNTIFS(RAW_DATA!$E$2:$E$48, A11, RAW_DATA!$D$2:$D$48, "Y") -> 5 | D11: =COUNTIFS(RAW_DATA!$E$2:$E$48, A11, RAW_DATA!$D$2:$D$48, "N") -> 4 | E11: =IFERROR(C11/B11, 0) -> 0.55555556 | F11: =COUNTIFS(RAW_DATA!$E$2:$E$48, A11, RAW_DATA!$G$2:$G$48, "진료완료") -> 9 | G11: =IFERROR(F11/B11, 0) -> 1 | H11: =SUMIFS(RAW_DATA!$I$2:$I$48, RAW_DATA!$E$2:$E$48, A11, RAW_DATA!$G$2:$G$48, "진료완료") -> 2645000 | I11: =SUMIFS(RAW_DATA!$I$2:$I$48, RAW_DATA!$E$2:$E$48, A11, RAW_DATA!$D$2:$D$48, "Y", RAW_DATA!$G$2:$G$48, "진료완료") -> 1595000 | J11: =SUMIFS(RAW_DATA!$I$2:$I$48, RAW_DATA!$E$2:$E$48, A11, RAW_DATA!$D$2:$D$48, "N", RAW_DATA!$G$2:$G$48, "진료완료") -> 1050000 | K11: =IFERROR(I11/H11, 0) -> 0.60302457
A12: 네이버검색 | B12: =COUNTIF(RAW_DATA!$E$2:$E$48, A12) -> 7 | C12: =COUNTIFS(RAW_DATA!$E$2:$E$48, A12, RAW_DATA!$D$2:$D$48, "Y") -> 4 | D12: =COUNTIFS(RAW_DATA!$E$2:$E$48, A12, RAW_DATA!$D$2:$D$48, "N") -> 3 | E12: =IFERROR(C12/B12, 0) -> 0.57142857 | F12: =COUNTIFS(RAW_DATA!$E$2:$E$48, A12, RAW_DATA!$G$2:$G$48, "진료완료") -> 3 | G12: =IFERROR(F12/B12, 0) -> 0.42857143 | H12: =SUMIFS(RAW_DATA!$I$2:$I$48, RAW_DATA!$E$2:$E$48, A12, RAW_DATA!$G$2:$G$48, "진료완료") -> 1260000 | I12: =SUMIFS(RAW_DATA!$I$2:$I$48, RAW_DATA!$E$2:$E$48, A12, RAW_DATA!$D$2:$D$48, "Y", RAW_DATA!$G$2:$G$48, "진료완료") -> 1140000 | J12: =SUMIFS(RAW_DATA!$I$2:$I$48, RAW_DATA!$E$2:$E$48, A12, RAW_DATA!$D$2:$D$48, "N", RAW_DATA!$G$2:$G$48, "진료완료") -> 120000 | K12: =IFERROR(I12/H12, 0) -> 0.9047619
A13: 당근마켓 | B13: =COUNTIF(RAW_DATA!$E$2:$E$48, A13) -> 5 | C13: =COUNTIFS(RAW_DATA!$E$2:$E$48, A13, RAW_DATA!$D$2:$D$48, "Y") -> 5 | D13: =COUNTIFS(RAW_DATA!$E$2:$E$48, A13, RAW_DATA!$D$2:$D$48, "N") -> 0 | E13: =IFERROR(C13/B13, 0) -> 1 | F13: =COUNTIFS(RAW_DATA!$E$2:$E$48, A13, RAW_DATA!$G$2:$G$48, "진료완료") -> 3 | G13: =IFERROR(F13/B13, 0) -> 0.6 | H13: =SUMIFS(RAW_DATA!$I$2:$I$48, RAW_DATA!$E$2:$E$48, A13, RAW_DATA!$G$2:$G$48, "진료완료") -> 850000 | I13: =SUMIFS(RAW_DATA!$I$2:$I$48, RAW_DATA!$E$2:$E$48, A13, RAW_DATA!$D$2:$D$48, "Y", RAW_DATA!$G$2:$G$48, "진료완료") -> 850000 | J13: =SUMIFS(RAW_DATA!$I$2:$I$48, RAW_DATA!$E$2:$E$48, A13, RAW_DATA!$D$2:$D$48, "N", RAW_DATA!$G$2:$G$48, "진료완료") -> 0 | K13: =IFERROR(I13/H13, 0) -> 1
A14: 지인추천 | B14: =COUNTIF(RAW_DATA!$E$2:$E$48, A14) -> 9 | C14: =COUNTIFS(RAW_DATA!$E$2:$E$48, A14, RAW_DATA!$D$2:$D$48, "Y") -> 4 | D14: =COUNTIFS(RAW_DATA!$E$2:$E$48, A14, RAW_DATA!$D$2:$D$48, "N") -> 5 | E14: =IFERROR(C14/B14, 0) -> 0.44444444 | F14: =COUNTIFS(RAW_DATA!$E$2:$E$48, A14, RAW_DATA!$G$2:$G$48, "진료완료") -> 7 | G14: =IFERROR(F14/B14, 0) -> 0.77777778 | H14: =SUMIFS(RAW_DATA!$I$2:$I$48, RAW_DATA!$E$2:$E$48, A14, RAW_DATA!$G$2:$G$48, "진료완료") -> 2105000 | I14: =SUMIFS(RAW_DATA!$I$2:$I$48, RAW_DATA!$E$2:$E$48, A14, RAW_DATA!$D$2:$D$48, "Y", RAW_DATA!$G$2:$G$48, "진료완료") -> 570000 | J14: =SUMIFS(RAW_DATA!$I$2:$I$48, RAW_DATA!$E$2:$E$48, A14, RAW_DATA!$D$2:$D$48, "N", RAW_DATA!$G$2:$G$48, "진료완료") -> 1535000 | K14: =IFERROR(I14/H14, 0) -> 0.27078385
A15: 재방문 | B15: =COUNTIF(RAW_DATA!$E$2:$E$48, A15) -> 10 | C15: =COUNTIFS(RAW_DATA!$E$2:$E$48, A15, RAW_DATA!$D$2:$D$48, "Y") -> 2 | D15: =COUNTIFS(RAW_DATA!$E$2:$E$48, A15, RAW_DATA!$D$2:$D$48, "N") -> 8 | E15: =IFERROR(C15/B15, 0) -> 0.2 | F15: =COUNTIFS(RAW_DATA!$E$2:$E$48, A15, RAW_DATA!$G$2:$G$48, "진료완료") -> 7 | G15: =IFERROR(F15/B15, 0) -> 0.7 | H15: =SUMIFS(RAW_DATA!$I$2:$I$48, RAW_DATA!$E$2:$E$48, A15, RAW_DATA!$G$2:$G$48, "진료완료") -> 2699000 | I15: =SUMIFS(RAW_DATA!$I$2:$I$48, RAW_DATA!$E$2:$E$48, A15, RAW_DATA!$D$2:$D$48, "Y", RAW_DATA!$G$2:$G$48, "진료완료") -> 220000 | J15: =SUMIFS(RAW_DATA!$I$2:$I$48, RAW_DATA!$E$2:$E$48, A15, RAW_DATA!$D$2:$D$48, "N", RAW_DATA!$G$2:$G$48, "진료완료") -> 2479000 | K15: =IFERROR(I15/H15, 0) -> 0.081511671
A16: 합계 | B16: =SUM(B10:B15) -> 47 | C16: =SUM(C10:C15) -> 22 | D16: =SUM(D10:D15) -> 25 | E16: =IFERROR(C16/B16, 0) -> 0.46808511 | F16: =SUM(F10:F15) -> 34 | G16: =IFERROR(F16/B16, 0) -> 0.72340426 | H16: =SUM(H10:H15) -> 13804000 | I16: =SUM(I10:I15) -> 4885000 | J16: =SUM(J10:J15) -> 8919000 | K16: =IFERROR(I16/H16, 0) -> 0.35388293
A18: 💉 [분석 2] 주요 시술 항목별 신환 vs 구환 매출 분석
A19: 시술 항목 | B19: 진료완료 건수 | C19: 신환 건수 | D19: 구환 건수 | E19: 총 수납금액(원) | F19: 신환 수납액(원) | G19: 구환 수납액(원) | H19: 신환 매출 기여율
A20: 울쎄라 300샷 | B20: =COUNTIFS(RAW_DATA!$H$2:$H$48, A20, RAW_DATA!$G$2:$G$48, "진료완료") -> 3 | C20: =COUNTIFS(RAW_DATA!$H$2:$H$48, A20, RAW_DATA!$D$2:$D$48, "Y", RAW_DATA!$G$2:$G$48, "진료완료") -> 1 | D20: =COUNTIFS(RAW_DATA!$H$2:$H$48, A20, RAW_DATA!$D$2:$D$48, "N", RAW_DATA!$G$2:$G$48, "진료완료") -> 2 | E20: =SUMIFS(RAW_DATA!$I$2:$I$48, RAW_DATA!$H$2:$H$48, A20, RAW_DATA!$G$2:$G$48, "진료완료") -> 3600000 | F20: =SUMIFS(RAW_DATA!$I$2:$I$48, RAW_DATA!$H$2:$H$48, A20, RAW_DATA!$D$2:$D$48, "Y", RAW_DATA!$G$2:$G$48, "진료완료") -> 1200000 | G20: =SUMIFS(RAW_DATA!$I$2:$I$48, RAW_DATA!$H$2:$H$48, A20, RAW_DATA!$D$2:$D$48, "N", RAW_DATA!$G$2:$G$48, "진료완료") -> 2400000 | H20: =IFERROR(F20/E20, 0) -> 0.33333333
A21: 써마지 600샷 | B21: =COUNTIFS(RAW_DATA!$H$2:$H$48, A21, RAW_DATA!$G$2:$G$48, "진료완료") -> 2 | C21: =COUNTIFS(RAW_DATA!$H$2:$H$48, A21, RAW_DATA!$D$2:$D$48, "Y", RAW_DATA!$G$2:$G$48, "진료완료") -> 0 | D21: =COUNTIFS(RAW_DATA!$H$2:$H$48, A21, RAW_DATA!$D$2:$D$48, "N", RAW_DATA!$G$2:$G$48, "진료완료") -> 2 | E21: =SUMIFS(RAW_DATA!$I$2:$I$48, RAW_DATA!$H$2:$H$48, A21, RAW_DATA!$G$2:$G$48, "진료완료") -> 2500000 | F21: =SUMIFS(RAW_DATA!$I$2:$I$48, RAW_DATA!$H$2:$H$48, A21, RAW_DATA!$D$2:$D$48, "Y", RAW_DATA!$G$2:$G$48, "진료완료") -> 0 | G21: =SUMIFS(RAW_DATA!$I$2:$I$48, RAW_DATA!$H$2:$H$48, A21, RAW_DATA!$D$2:$D$48, "N", RAW_DATA!$G$2:$G$48, "진료완료") -> 2500000 | H21: =IFERROR(F21/E21, 0) -> 0
A22: 울쎄라 600샷 | B22: =COUNTIFS(RAW_DATA!$H$2:$H$48, A22, RAW_DATA!$G$2:$G$48, "진료완료") -> 1 | C22: =COUNTIFS(RAW_DATA!$H$2:$H$48, A22, RAW_DATA!$D$2:$D$48, "Y", RAW_DATA!$G$2:$G$48, "진료완료") -> 0 | D22: =COUNTIFS(RAW_DATA!$H$2:$H$48, A22, RAW_DATA!$D$2:$D$48, "N", RAW_DATA!$G$2:$G$48, "진료완료") -> 1 | E22: =SUMIFS(RAW_DATA!$I$2:$I$48, RAW_DATA!$H$2:$H$48, A22, RAW_DATA!$G$2:$G$48, "진료완료") -> 2200000 | F22: =SUMIFS(RAW_DATA!$I$2:$I$48, RAW_DATA!$H$2:$H$48, A22, RAW_DATA!$D$2:$D$48, "Y", RAW_DATA!$G$2:$G$48, "진료완료") -> 0 | G22: =SUMIFS(RAW_DATA!$I$2:$I$48, RAW_DATA!$H$2:$H$48, A22, RAW_DATA!$D$2:$D$48, "N", RAW_DATA!$G$2:$G$48, "진료완료") -> 2200000 | H22: =IFERROR(F22/E22, 0) -> 0
A23: 피코토닝 10회 | B23: =COUNTIFS(RAW_DATA!$H$2:$H$48, A23, RAW_DATA!$G$2:$G$48, "진료완료") -> 2 | C23: =COUNTIFS(RAW_DATA!$H$2:$H$48, A23, RAW_DATA!$D$2:$D$48, "Y", RAW_DATA!$G$2:$G$48, "진료완료") -> 1 | D23: =COUNTIFS(RAW_DATA!$H$2:$H$48, A23, RAW_DATA!$D$2:$D$48, "N", RAW_DATA!$G$2:$G$48, "진료완료") -> 1 | E23: =SUMIFS(RAW_DATA!$I$2:$I$48, RAW_DATA!$H$2:$H$48, A23, RAW_DATA!$G$2:$G$48, "진료완료") -> 1700000 | F23: =SUMIFS(RAW_DATA!$I$2:$I$48, RAW_DATA!$H$2:$H$48, A23, RAW_DATA!$D$2:$D$48, "Y", RAW_DATA!$G$2:$G$48, "진료완료") -> 850000 | G23: =SUMIFS(RAW_DATA!$I$2:$I$48, RAW_DATA!$H$2:$H$48, A23, RAW_DATA!$D$2:$D$48, "N", RAW_DATA!$G$2:$G$48, "진료완료") -> 850000 | H23: =IFERROR(F23/E23, 0) -> 0.5
A24: 쥬베룩 볼륨 | B24: =COUNTIFS(RAW_DATA!$H$2:$H$48, A24, RAW_DATA!$G$2:$G$48, "진료완료") -> 2 | C24: =COUNTIFS(RAW_DATA!$H$2:$H$48, A24, RAW_DATA!$D$2:$D$48, "Y", RAW_DATA!$G$2:$G$48, "진료완료") -> 2 | D24: =COUNTIFS(RAW_DATA!$H$2:$H$48, A24, RAW_DATA!$D$2:$D$48, "N", RAW_DATA!$G$2:$G$48, "진료완료") -> 0 | E24: =SUMIFS(RAW_DATA!$I$2:$I$48, RAW_DATA!$H$2:$H$48, A24, RAW_DATA!$G$2:$G$48, "진료완료") -> 900000 | F24: =SUMIFS(RAW_DATA!$I$2:$I$48, RAW_DATA!$H$2:$H$48, A24, RAW_DATA!$D$2:$D$48, "Y", RAW_DATA!$G$2:$G$48, "진료완료") -> 900000 | G24: =SUMIFS(RAW_DATA!$I$2:$I$48, RAW_DATA!$H$2:$H$48, A24, RAW_DATA!$D$2:$D$48, "N", RAW_DATA!$G$2:$G$48, "진료완료") -> 0 | H24: =IFERROR(F24/E24, 0) -> 1
A25: 리쥬란힐러 2cc | B25: =COUNTIFS(RAW_DATA!$H$2:$H$48, A25, RAW_DATA!$G$2:$G$48, "진료완료") -> 2 | C25: =COUNTIFS(RAW_DATA!$H$2:$H$48, A25, RAW_DATA!$D$2:$D$48, "Y", RAW_DATA!$G$2:$G$48, "진료완료") -> 2 | D25: =COUNTIFS(RAW_DATA!$H$2:$H$48, A25, RAW_DATA!$D$2:$D$48, "N", RAW_DATA!$G$2:$G$48, "진료완료") -> 0 | E25: =SUMIFS(RAW_DATA!$I$2:$I$48, RAW_DATA!$H$2:$H$48, A25, RAW_DATA!$G$2:$G$48, "진료완료") -> 580000 | F25: =SUMIFS(RAW_DATA!$I$2:$I$48, RAW_DATA!$H$2:$H$48, A25, RAW_DATA!$D$2:$D$48, "Y", RAW_DATA!$G$2:$G$48, "진료완료") -> 580000 | G25: =SUMIFS(RAW_DATA!$I$2:$I$48, RAW_DATA!$H$2:$H$48, A25, RAW_DATA!$D$2:$D$48, "N", RAW_DATA!$G$2:$G$48, "진료완료") -> 0 | H25: =IFERROR(F25/E25, 0) -> 1
A26: 인모드 FORMA | B26: =COUNTIFS(RAW_DATA!$H$2:$H$48, A26, RAW_DATA!$G$2:$G$48, "진료완료") -> 1 | C26: =COUNTIFS(RAW_DATA!$H$2:$H$48, A26, RAW_DATA!$D$2:$D$48, "Y", RAW_DATA!$G$2:$G$48, "진료완료") -> 0 | D26: =COUNTIFS(RAW_DATA!$H$2:$H$48, A26, RAW_DATA!$D$2:$D$48, "N", RAW_DATA!$G$2:$G$48, "진료완료") -> 1 | E26: =SUMIFS(RAW_DATA!$I$2:$I$48, RAW_DATA!$H$2:$H$48, A26, RAW_DATA!$G$2:$G$48, "진료완료") -> 150000 | F26: =SUMIFS(RAW_DATA!$I$2:$I$48, RAW_DATA!$H$2:$H$48, A26, RAW_DATA!$D$2:$D$48, "Y", RAW_DATA!$G$2:$G$48, "진료완료") -> 0 | G26: =SUMIFS(RAW_DATA!$I$2:$I$48, RAW_DATA!$H$2:$H$48, A26, RAW_DATA!$D$2:$D$48, "N", RAW_DATA!$G$2:$G$48, "진료완료") -> 150000 | H26: =IFERROR(F26/E26, 0) -> 0
A27: 사각턱보톡스 | B27: =COUNTIFS(RAW_DATA!$H$2:$H$48, A27, RAW_DATA!$G$2:$G$48, "진료완료") -> 5 | C27: =COUNTIFS(RAW_DATA!$H$2:$H$48, A27, RAW_DATA!$D$2:$D$48, "Y", RAW_DATA!$G$2:$G$48, "진료완료") -> 1 | D27: =COUNTIFS(RAW_DATA!$H$2:$H$48, A27, RAW_DATA!$D$2:$D$48, "N", RAW_DATA!$G$2:$G$48, "진료완료") -> 4 | E27: =SUMIFS(RAW_DATA!$I$2:$I$48, RAW_DATA!$H$2:$H$48, A27, RAW_DATA!$G$2:$G$48, "진료완료") -> 225000 | F27: =SUMIFS(RAW_DATA!$I$2:$I$48, RAW_DATA!$H$2:$H$48, A27, RAW_DATA!$D$2:$D$48, "Y", RAW_DATA!$G$2:$G$48, "진료완료") -> 45000 | G27: =SUMIFS(RAW_DATA!$I$2:$I$48, RAW_DATA!$H$2:$H$48, A27, RAW_DATA!$D$2:$D$48, "N", RAW_DATA!$G$2:$G$48, "진료완료") -> 180000 | H27: =IFERROR(F27/E27, 0) -> 0.2
A28: 기타 시술 | B28: =B16-SUM(B20:B27) -> 29 | C28: =C16-SUM(C20:C27) -> 15 | D28: =D16-SUM(D20:D27) -> 14 | E28: =H16-SUM(E20:E27) -> 1949000 | F28: =I16-SUM(F20:F27) -> 1310000 | G28: =J16-SUM(G20:G27) -> 639000 | H28: =IFERROR(F28/E28, 0) -> 0.67213956
A29: 합계 | B29: =SUM(B20:B28) -> 47 | C29: =SUM(C20:C28) -> 22 | D29: =SUM(D20:D28) -> 25 | E29: =SUM(E20:E28) -> 13804000 | F29: =SUM(F20:F28) -> 4885000 | G29: =SUM(G20:G28) -> 8919000 | H29: =IFERROR(F29/E29, 0) -> 0.35388293
A31: ⚠️ [분석 3] 채널별 노쇼(No-Show) 및 예약 취소율 분석 (이탈 리스크 매트릭스)
A32: 유입 채널 | B32: 전체 예약 | C32: 노쇼(No-Show) | D32: 예약 취소 | E32: 총 이탈 건수 | F32: 노쇼율 | G32: 취소율 | H32: 전체 이탈률 | I32: 리스크 등급 | J32: 채널별 대응 전략 제언
A33: 인스타그램 | B33: =COUNTIF(RAW_DATA!$E$2:$E$48, A33) -> 7 | C33: =COUNTIFS(RAW_DATA!$E$2:$E$48, A33, RAW_DATA!$G$2:$G$48, "노쇼") -> 1 | D33: =COUNTIFS(RAW_DATA!$E$2:$E$48, A33, RAW_DATA!$G$2:$G$48, "예약취소") -> 1 | E33: =C33+D33 -> 2 | F33: =IFERROR(C33/B33, 0) -> 0.14285714 | G33: =IFERROR(D33/B33, 0) -> 0.14285714 | H33: =IFERROR(E33/B33, 0) -> 0.28571429 | I33: =IF(H33>=0.4, "고위험", IF(H33>=0.2, "주의", "안정")) -> 주의 | J33: 예약금(Deposit) 도입 및 시술 당일 잔금 완납 프로토콜 필요
A34: 카카오톡 | B34: =COUNTIF(RAW_DATA!$E$2:$E$48, A34) -> 9 | C34: =COUNTIFS(RAW_DATA!$E$2:$E$48, A34, RAW_DATA!$G$2:$G$48, "노쇼") -> 0 | D34: =COUNTIFS(RAW_DATA!$E$2:$E$48, A34, RAW_DATA!$G$2:$G$48, "예약취소") -> 0 | E34: =C34+D34 -> 0 | F34: =IFERROR(C34/B34, 0) -> 0 | G34: =IFERROR(D34/B34, 0) -> 0 | H34: =IFERROR(E34/B34, 0) -> 0 | I34: =IF(H34>=0.4, "고위험", IF(H34>=0.2, "주의", "안정")) -> 안정 | J34: 최우수 안정 채널 - 리텐션 프로그램 및 충성고객 락인 강화
A35: 네이버검색 | B35: =COUNTIF(RAW_DATA!$E$2:$E$48, A35) -> 7 | C35: =COUNTIFS(RAW_DATA!$E$2:$E$48, A35, RAW_DATA!$G$2:$G$48, "노쇼") -> 2 | D35: =COUNTIFS(RAW_DATA!$E$2:$E$48, A35, RAW_DATA!$G$2:$G$48, "예약취소") -> 2 | E35: =C35+D35 -> 4 | F35: =IFERROR(C35/B35, 0) -> 0.28571429 | G35: =IFERROR(D35/B35, 0) -> 0.28571429 | H35: =IFERROR(E35/B35, 0) -> 0.57142857 | I35: =IF(H35>=0.4, "고위험", IF(H35>=0.2, "주의", "안정")) -> 고위험 | J35: 예약 전일/당일 리마인드 알림톡 필수 발송 및 가변 스케줄링 배정
A36: 당근마켓 | B36: =COUNTIF(RAW_DATA!$E$2:$E$48, A36) -> 5 | C36: =COUNTIFS(RAW_DATA!$E$2:$E$48, A36, RAW_DATA!$G$2:$G$48, "노쇼") -> 1 | D36: =COUNTIFS(RAW_DATA!$E$2:$E$48, A36, RAW_DATA!$G$2:$G$48, "예약취소") -> 1 | E36: =C36+D36 -> 2 | F36: =IFERROR(C36/B36, 0) -> 0.2 | G36: =IFERROR(D36/B36, 0) -> 0.2 | H36: =IFERROR(E36/B36, 0) -> 0.4 | I36: =IF(H36>=0.4, "고위험", IF(H36>=0.2, "주의", "안정")) -> 고위험 | J36: 예약 리컨펌 확인 및 노쇼 패널티 규정 안내
A37: 지인추천 | B37: =COUNTIF(RAW_DATA!$E$2:$E$48, A37) -> 9 | C37: =COUNTIFS(RAW_DATA!$E$2:$E$48, A37, RAW_DATA!$G$2:$G$48, "노쇼") -> 2 | D37: =COUNTIFS(RAW_DATA!$E$2:$E$48, A37, RAW_DATA!$G$2:$G$48, "예약취소") -> 0 | E37: =C37+D37 -> 2 | F37: =IFERROR(C37/B37, 0) -> 0.22222222 | G37: =IFERROR(D37/B37, 0) -> 0 | H37: =IFERROR(E37/B37, 0) -> 0.22222222 | I37: =IF(H37>=0.4, "고위험", IF(H37>=0.2, "주의", "안정")) -> 주의 | J37: 소개자 리워드 혜택 연계로 이탈 방지 및 충성도 유지
A38: 재방문 | B38: =COUNTIF(RAW_DATA!$E$2:$E$48, A38) -> 10 | C38: =COUNTIFS(RAW_DATA!$E$2:$E$48, A38, RAW_DATA!$G$2:$G$48, "노쇼") -> 1 | D38: =COUNTIFS(RAW_DATA!$E$2:$E$48, A38, RAW_DATA!$G$2:$G$48, "예약취소") -> 2 | E38: =C38+D38 -> 3 | F38: =IFERROR(C38/B38, 0) -> 0.1 | G38: =IFERROR(D38/B38, 0) -> 0.2 | H38: =IFERROR(E38/B38, 0) -> 0.3 | I38: =IF(H38>=0.4, "고위험", IF(H38>=0.2, "주의", "안정")) -> 주의 | J38: 기존 고객 케어 알림 및 정기 시술 리콜 안내
A39: 합계 / 평균 | B39: =SUM(B33:B38) -> 47 | C39: =SUM(C33:C38) -> 7 | D39: =SUM(D33:D38) -> 6 | E39: =SUM(E33:E38) -> 13 | F39: =IFERROR(C39/B39, 0) -> 0.14893617 | G39: =IFERROR(D39/B39, 0) -> 0.12765957 | H39: =IFERROR(E39/B39, 0) -> 0.27659574 | I39: =IF(H39>=0.4, "고위험", IF(H39>=0.2, "주의", "안정")) -> 주의 | J39: 전체 예약 중 이탈 방지를 위한 통합 CRM 리마인드 프로세스 구축 필요

Sheet ERD_및_SQL쿼리
A1: 🗄️ [전산 / DB 엔지니어링] 의료 MSO 관계형 데이터 모델(ERD) 및 Data Pipeline SQL
A2: HeidiSQL / MySQL 기반 정규화 테이블 스키마 설계 및 데이터 이상치 탐지·보정·KPI 산출 쿼리 세트
A4: 📐 [섹션 1] 관계형 데이터 모델링 (Relational Schema & ERD Architecture)
A5: 테이블명 | B5: 필드명 (Column Name) | C5: 데이터 타입 (Data Type) | D5: 제약조건 (Constraints) | E5: 외래키 관계 (Relationship) | F5: 설명 (Description) | G5: 비고
A6: customer_master | B6: Chart_No | C6: VARCHAR(20) | D6: PRIMARY KEY, NOT NULL | E6: - | F6: 환자 고유 차트번호 (C250011 ~) | G6: 기준정보 마스터
A7: customer_master | B7: Customer_ID | C7: VARCHAR(20) | D7: UNIQUE, NOT NULL | E7: - | F7: 회원 로그인 식별자 (U1011 ~) | G7: 고객 식별키
A8: customer_master | B8: Customer_Name | C8: VARCHAR(50) | D8: NOT NULL | E8: - | F8: 환자 성명 (마스킹: 김*수) | G8: 개인정보 보호
A9: customer_master | B9: Phone_Number | C9: VARCHAR(20) | D9: NOT NULL | E9: - | F9: 연락처 (마스킹) | G9: 알림톡 발송용
A10: customer_master | B10: Customer_Grade | C10: ENUM('일반','우수','VIP') | D10: DEFAULT '일반' | E10: - | F10: 고객 CRM 등급 | G10: 세그먼트 기준
A11: customer_master | B11: Join_Date | C11: DATE | D11: NOT NULL | E11: - | F11: 최초 회원 가입일자 | G11: 신환/구환 기준일
A12: crm_transaction_log | B12: Reservation_Date | C12: DATE | D12: NOT NULL | E12: - | F12: 예약 및 결제 일자 | G12: 일일 파티션 키
A13: crm_transaction_log | B13: Reservation_Time | C13: TIME | D13: NOT NULL | E13: - | F13: 예약 시간 (타임슬롯) | G13: 시간대별 분석
A14: crm_transaction_log | B14: Chart_No | C14: VARCHAR(20) | D14: FOREIGN KEY, NOT NULL | E14: customer_master (1:N) | F14: 환자 차트번호 (참조 무결성 보장) | G14: 외래키(FK)
A15: crm_transaction_log | B15: Is_First_Visit | C15: CHAR(1) | D15: CHECK (IN ('Y', 'N')) | E15: - | F15: 초진(신환: Y) / 재진(구환: N) 여부 | G15: 마케팅 지표
A16: crm_transaction_log | B16: Inflow_Channel | C16: VARCHAR(50) | D16: ENUM 정의 권장 | E16: - | F16: 마케팅 유입 채널 (인스타, 카톡 등) | G16: CAC 및 전환율
... A21: crm_transaction_log | B21: Unpaid_Amount | C21: INT | D21: CHECK (>= 0), DEFAULT 0 | E21: - | F21: 미수 잔금 (원) | G21: 채권 리스크 관리
A23: 💻 [섹션 2] Data QA 이상치 탐지 및 자동 정제 MySQL SQL 쿼리 세트
A24: 쿼리 번호 | B24: 분류 (Type) | C24: 쿼리 목적 및 설명 | D24: SQL 소스 코드 (MySQL / MariaDB / HeidiSQL) | E24: 실행 결과 및 영향도 | F24: 비고
A25: SQL-QA-01 | B25: 이상치 탐지 | C25: 기준정보 누락 검증 (Master Unregistered): 회원 마스터에 미등록된 이상 차트번호 탐지 (총 3건) | D25: -- 1. 고객 마스터 미등록 이상 차트번호 탐지 SELECT t.Reservation_Date, t.Chart_No, t.Treatment_Item, t.Payment_Amount FROM crm_transaction_log t LEFT JOIN customer_master c ON t.Chart_No = c.Chart_No WHERE c.Chart_No IS NULL; | E25: 마스터 미등록 이상치 3건 즉시 탐지 -> 원무팀 확인 후 기준정보 동기화 완료 | F25: 참조 무결성 검증
A26: SQL-QA-02 | B26: 데이터 보정 | C26: 비즈니스 모순 보정 (Logic Error Fix): 노쇼/취소 상태임에도 잔존하는 결제액·잔금 0원 보정 (총 5건) | D26: -- 2. 노쇼 및 예약취소 건의 비정상 수납액 및 잔금 0원 일괄 보정 UPDATE crm_transaction_log SET Payment_Amount = 0, Unpaid_Amount = 0 WHERE Reservation_Status IN ('노쇼', '예약취소') AND (Payment_Amount > 0 OR Unpaid_Amount > 0); | E26: 모순 데이터 5건 0원 보정 처리 완료 (가공 매출 왜곡 원천 차단) | F26: 트랜잭션 정합성 확보
A27: SQL-QA-03 | B27: 데이터 정제 | C27: 수납 이상치 보정 (Negative Value Fix): 잔금이 음수(-20,000원)로 오입력된 오류 0원 정상화 (1건) | D27: -- 3. 잔금 음수 오입력 이상치 탐지 및 정상화 조치 UPDATE crm_transaction_log SET Unpaid_Amount = 0 WHERE Unpaid_Amount < 0; | E27: 음수 오입력 1건 정상화 완료 (미수 잔금 집계 오류 해결) | F27: 데이터 무결성 복구
A29: 📊 [섹션 3] 일일 경영 KPI 및 채널 성과 자동 집계 SQL 쿼리
A30: 쿼리 번호 | B30: 분류 (Type) | C30: 분석 목적 및 집계 로직 | D30: SQL 소스 코드 (MySQL / MariaDB / HeidiSQL) | E30: 산출 지표 및 활용 방안 | F30: 비고
A31: SQL-KPI-01 | B31: 경영 지표 | C31: 일자별 핵심 경영 KPI 요약 집계 (수납액, 미수금, 완료건, 신환수) | D31: -- 일자별 총 수납액, 미수 잔금, 진료 완료 건수, 신환 유입 건수 집계 SELECT Reservation_Date, COUNT(CASE WHEN Reservation_Status = '진료완료' THEN 1 END) AS Completed_Count, COUNT(CASE WHEN Reservation_Status = '노쇼' THEN 1 END) AS NoShow_Count, COUNT(CASE WHEN Reservation_Status = '예약취소' THEN 1 END) AS Cancel_Count, COUNT(CASE WHEN Is_First_Visit = 'Y' AND Reservation_Status = '진료완료' THEN 1 END) AS New_Patients, SUM(CASE WHEN Reservation_Status = '진료완료' THEN Payment_Amount ELSE 0 END) AS Total_Revenue, SUM(CASE WHEN Reservation_Status = '진료완료' THEN Unpaid_Amount ELSE 0 END) AS Total_Unpaid FROM crm_transaction_log GROUP BY Reservation_Date ORDER BY Reservation_Date; | E31: 일일 매출 마감 대사표 및 원장단 일일 브리핑 자동화 리포트 생성 | F31: 일일 마감 집계
A32: SQL-KPI-02 | B32: 마케팅 분석 | C32: 유입 채널별 신환/구환 매출 기여도 및 이탈(노쇼/취소) 통합 성과 분석 | D32: -- 유입 채널별 성과 매트릭스 (수납액, 이탈률, 신환 비중) SELECT Inflow_Channel, COUNT(*) AS Total_Reservations, SUM(CASE WHEN Is_First_Visit = 'Y' THEN 1 ELSE 0 END) AS New_Patient_Count, ROUND(SUM(CASE WHEN Is_First_Visit = 'Y' THEN 1 ELSE 0 END) / COUNT(*) * 100, 1) AS New_Patient_Rate, SUM(CASE WHEN Reservation_Status = '진료완료' THEN Payment_Amount ELSE 0 END) AS Completed_Revenue, SUM(CASE WHEN Reservation_Status = '진료완료' THEN Unpaid_Amount ELSE 0 END) AS Total_Unpaid, ROUND(SUM(CASE WHEN Reservation_Status IN ('노쇼', '예약취소') THEN 1 ELSE 0 END) / COUNT(*) * 100, 1) AS Drop_Rate FROM crm_transaction_log GROUP BY Inflow_Channel ORDER BY Completed_Revenue DESC; | E32: 마케팅 채널별 ROAS 분석, 예산 재배분 및 예약금(Deposit) 정책 수립 근거 제공 | F32: 채널 ROI 최적화

Sheet Data_QA_Validation규칙
A1: 🛡️ [데이터 운영 거버넌스] 트랜잭션 입력단 Validation & 재발 방지 검증 규칙서
A2: CRM/EMR 수납 및 예약 트랜잭션 데이터 무결성 보장을 위한 시스템 제약 조건(Constraint) 및 운영 정제 정책 명세
A4: 📋 [매트릭스 1] 데이터 무결성 검증 규칙 (Data Validation Rule Matrix)
A5: 규칙 ID | B5: 검증 대상 필드 | C5: 검증 유형 | D5: 이상치/에러 발생 시나리오 | E5: 입력단 시스템 차단 규칙 (System Constraint) | F5: 사후 조치 및 정제 가이드 (QA Policy) | G5: 관리 책임 부서
A6: VAL_01 | B6: Chart_No | C6: 참조 무결성 (Referential) | D6: 회원 마스터에 미등록된 임의/오타 차트번호 입력 (3건 발생) | E6: FOREIGN KEY (Chart_No) REFERENCES customer_master(Chart_No) ON UPDATE CASCADE | F6: 원무팀 즉시 확인 후 신규 차트 등록 또는 오타 보정 동기화 | G6: 원무과 / CRM운영팀
A7: VAL_02 | B7: Reservation_Status, Payment, Unpaid | C7: 비즈니스 로직 (Business Logic) | D7: 예약 취소/노쇼 상태임에도 결제액·잔금이 잔존 (5건 발생) | E7: CHECK ((Reservation_Status IN ('노쇼', '예약취소') AND Payment_Amount = 0 AND Unpaid_Amount = 0) OR (Reservation_Status = '진료완료')) | F7: 취소/노쇼 확정 시 결제액 및 잔금 필드 0원 자동 초기화 트리거 실행 | G7: 수납데스크 / 전산팀
A8: VAL_03 | B8: Unpaid_Amount | C8: 범위 제약 (Range Check) | D8: 수납 기입 오류로 미수 잔금이 음수(-20,000원)로 오입력 (1건 발생) | E8: CHECK (Unpaid_Amount >= 0 AND Payment_Amount >= 0) | F8: 수납 단말기 승인 내역 및 환불 영수증 대사 후 잔금 0원 정상화 조치 | G8: 정산관리팀
A9: VAL_04 | B9: Payment_Amount, Unpaid_Amount | C9: 논리 정합성 (Logic Integrity) | D9: 수납액과 잔금의 합계가 시술 정가 수가(수가 마스터)와 불일치 | E9: CHECK (Payment_Amount + Unpaid_Amount = Item_Standard_Price * Discount_Rate) | F9: 할인율 프로모션 코드 누락 여부 확인 및 원장 결재 확인 후 승인 | G9: 원무수납 / 경영기획
A10: VAL_05 | B10: Reservation_Time | C10: 형식 및 도메인 (Format & Range) | D10: 진료 외 시간(야간, 휴무일 등) 또는 잘못된 시간 형식 입력 | E10: CHECK (Reservation_Time BETWEEN '09:30:00' AND '19:30:00') | F10: 예약 캘린더 타임슬롯 기반 강제 선택 UI(드롭다운) 적용으로 수기 입력 차단 | G10: 예약상담실 / 전산팀
A11: VAL_06 | B11: Inflow_Channel | C11: 도메인 무결성 (Enum) | D11: 미정의 유입경로 기입 또는 띄어쓰기 오타('인스타 ', '네이버 ') | E11: ENUM('인스타그램', '카카오톡', '네이버검색', '당근마켓', '지인추천', '재방문') | F11: 자유 텍스트 입력 금지, 표준화된 유입채널 단일 선택 칩(Chip) 적용 | G11: 마케팅팀 / EMR운영
A12: VAL_07 | B12: Is_First_Visit | C12: 상태 일관성 (State Consistency) | D12: 과거 진료 이력이 존재함에도 신환('Y')으로 잘못 체크 | E12: 자동 산출 필드로 전환: IF(COUNT(이전자격이력) = 0, 'Y', 'N') 시스템 산출 | F12: 사용자 수기 체크박스 비활성화 및 차트번호 기반 백엔드 자동 판별 | G12: CRM전산팀
A14: 🔄 [매트릭스 2] Data QA 운영 주기 및 일일 마감 점검 프로세스 (QA Operating Cycle)
A15: 점검 단계 | B15: 점검 시점 | C15: 점검 대상 및 방법 | D15: 통과 기준 (SLA) | E15: 오류 발견 시 대응 조치 (Escalation) | F15: 보고 대상 | G15: 비고
A16: 1단계: 입력단 실시간 검증 | B16: 데이터 생성 즉시 | C16: EMR/CRM 입력 폼 유효성 검사 스크립트 실행 | D16: 이상치 발생률 0% (차단율 100%) | E16: 입력 팝업 경고창 출력 및 저장 버튼 비활성화 | F16: 원무/상담 현장 입력자 | G16: 프론트엔드 유효성 검사
A17: 2단계: 일일 마감 대사 QA | B17: 매일 19:30 (진료 종료 직후) | C17: PG 카드사 실매출 전표 vs EMR 결제 데이터 1:1 대사 | D17: 불일치 금액 0원 (오차 0%) | E17: 불일치 건 즉시 추적 후 일일 마감 전 정정 전표 발행 | F17: 원무과장, 총괄실장 | G17: SQL 대사 쿼리 배치 실행
A18: 3단계: 예약 및 이탈 데이터 QA | B18: 익일 09:00 (진료 개시 전) | C18: 전일 노쇼/취소 환자 잔여 결제액 및 미수 잔금 전수 검증 | D18: 노쇼/취소 건 잔금 잔존 0건 | E18: 원무팀 소명 요청 및 미수 데이터 0원 보정 승인 | F18: CRM 운영팀장 | G18: 자동 보정 트리거 동작 확인
A19: 4단계: 월간 마감 및 거버넌스 | B19: 익월 1영업일 | C19: 월간 이상치 발생 건수 및 유형별 원인 분석 리포트 발행 | D19: 월간 QA 이상치 0건 목표 | E19: EMR 시스템 제약조건 패치 및 원무팀 재발방지 교육 | F19: MSO 경영진 / 이사회 | G19: 경영진 의사결정 보고

Sheet GitHub_README_포트폴리오
A1: 구분 | B1: GitHub README.md 마크다운 원문 (Ctrl+C 복사 후 바로 사용 가능) | C1: 채용담당자 / 면접관 관점의 핵심 평가 포인트 (Recruiter Review Point)
A2: HEADER | B2: # 🏥 [포트폴리오] 의료 MSO 비즈니스 데이터 파이프라인 & CRM Data QA > **의료 MSO 환경의 결제·예약 트랜잭션 데이터 무결성 검증 및 일일 경영 의사결정 대시보드 구축** [![Tech Stack](https://img.shields.io/badge/Stack-MySQL%20%7C%20HeidiSQL%20%7C%20GoogleSheets%20%7C%20Excel-blue)](https://github.com) [![Data QA](https://img.shields.io/badge/Data%20QA-9%20Errors%20Cleaned%20(100%25)-success)](https://github.com) [![Role](https://img.shields.io/badge/Target%20Role-Data%20Analyst%20%7C%20Data%20Ops%20%7C%20EMR%20IT-orange)](https://github.com) | C2: • 직관적인 배지와 헤더로 지원자의 기술 스택 및 프로젝트 성격 명확화 • 분석/운영/전산 세 가지 직무 모두에 어필 가능한 멀티 역량 강조
A3: SEC_01 | B3: --- ## 📌 1. 프로젝트 배경 및 목적 (Background & Objectives) * **비즈니스 배경**: 피부과·성형외과 등 비급여 의료 MSO에서는 일일 30~50건 이상의 예약, 결제, 노쇼(No-Show) 트랜잭션이 발생하며, 프론트 수기 기입으로 인한 결제 누락 및 이상치가 발생하기 쉽습니다. * **프로젝트 목표**: 1. **데이터 무결성 검증 (Data QA)**: 회원 마스터 미등록, 취소 건 결제 잔존 등 이상치를 전수 정제하여 데이터 신뢰도 100% 확보. 2. **일일 경영 KPI 대시보드화**: 총 수납금액, 미수 잔금, 신환/구환 유입률을 실시간 집계하는 운영 대시보드 구축. 3. **재발 방지 거버넌스 수립**: EMR 입력단 제약조건 및 일일 마감 대사 프로세스를 설계하여 시스템적 오류 방지. | C3: • 단순 툴 활용이 아닌 비즈니스 문제 정의 및 경영 기여 목표 제시 • 의료 MSO의 도메인 특성(비급여 시술, 노쇼 리스크)을 정확히 이해하고 있음을 입증
A4: SEC_02 | B4: --- ## 🔍 2. 핵심 데이터 정합성 검증 (Data QA 내역 - 9건 정제) EMR/CRM 트랜잭션 로그 47건 중 **총 9건의 치명적 이상치를 탐지 및 정제**하였습니다. | 구분 | 검증 유형 | 에러 탐지 내용 및 건수 | 원인 분석 | 정제 및 조치 결과 | |:---:|:---:|:---|:---|:---| | **QA-01** | **기준정보 누락** | 회원 마스터 미등록 차트번호 **3건** | EMR 차트 채번 전 예약 로그 선입력 | 마스터 테이블과 VLOOKUP 대사 후 신규 등록 동기화 | | **QA-02** | **비즈니스 모순** | 예약 취소·노쇼 건 결제액/잔금 잔존 **5건** | 예약 상태 변경 시 수납액 미취소 전산 누락 | 결제금액 및 미수 잔금 **0원 일괄 보정** (매출 왜곡 원천 차단) | | **QA-03** | **수납 이상치** | 미수 잔금이 음수(-20,000원) 입력 **1건** | 부분 환불/프로모션 차감 시 오입력 | 카드 승인 내역 대사 후 잔금 0원 정상화 조치 | | C4: • 지원자의 실제 문제 해결 역량(Troubleshooting)을 구체적 수치로 증명 • 매출 왜곡(가공 매출)을 사전에 차단한 비즈니스 임팩트 부각
A5: SEC_03 | B5: --- ## 🛡️ 3. 데이터 운영 및 재발 방지 거버넌스 (Data Governance) 사후 정제에 그치지 않고, **시스템 입력단에서 이상치를 원천 차단**하는 데이터 운영 거버넌스를 설계하였습니다. ```sql -- 1. 회원 마스터 참조 무결성 외래키 제약 (Foreign Key) ALTER TABLE crm_transaction_log ADD CONSTRAINT fk_chart_no FOREIGN KEY (Chart_No) REFERENCES customer_master(Chart_No); -- 2. 비즈니스 로직 제약 조건 (CHECK Constraint) ALTER TABLE crm_transaction_log ADD CONSTRAINT chk_cancel_zero_payment CHECK ((Reservation_Status IN ('노쇼', '예약취소') AND Payment_Amount = 0 AND Unpaid_Amount = 0) OR (Reservation_Status = '진료완료')); -- 3. 잔금 음수 방지 제약 조건 ALTER TABLE crm_transaction_log ADD CONSTRAINT chk_positive_unpaid CHECK (Unpaid_Amount >= 0 AND Payment_Amount >= 0); ``` ### 🔄 4단계 QA 운영 사이클 1. **1단계 (실시간)**: EMR 프론트엔드 입력 폼 유효성 검사 (마스터 외 차트번호 차단, 필수값 검증) 2. **2단계 (19:30 일일마감)**: PG 카드사 승인 내역과 EMR 수납액 1:1 대사 SQL 배치 실행 3. **3단계 (익일 09:00)**: 전일 노쇼/취소 환자 잔여 결제액 0원 보정 여부 전수 감사 4. **4단계 (월간결산)**: 월간 이상치 제로(Zero-Defect) 거버넌스 리포트 경영진 보고 | C5: • 데이터 운영(Data Operations) 및 데이터 엔지니어링 직무의 핵심 역량 증명 • 일회성 분석을 넘어선 프로세스 자동화 및 거버넌스 설계 능력 어필
A6: SEC_04 | B6: --- ## 🗄️ 4. 데이터베이스 모델링 & ERD (Data Architecture) 정규화(Normalization) 원칙에 따라 데이터 구조를 설계하여 중복을 최소화하고 확장성을 확보하였습니다. * **customer_master (1)** ──< **crm_transaction_log (N)**: 환자 기준정보 및 이력 관리 * **treatment_master (1)** ──< **crm_transaction_log (N)**: 시술 표준 수가표 관리 * **consultant_master (1)** ──< **crm_transaction_log (N)**: 상담 실장별 매출 인센티브 추적 | C6: • 전산 및 데이터베이스 설계(RDBMS) 역량 명시 • 확장 가능한 구조를 설계할 수 있는 IT 감각 증명
A7: SEC_05 | B7: --- ## 📊 5. 핵심 경영 인사이트 및 전략적 제언 (Key Insights & Action Plan) * **총 수납금액**: 13,804,000원 (진료 완료 34건) | **총 미수 잔금**: 900,000원 | **전체 예약**: 47건 ### 💡 채널별 성과 및 실행 제언 1. **인스타그램 (최고 매출 견인 & 미수금 리스크 집중)**: * 전체 매출의 **30.8%(4,245,000원)**를 견인하는 핵심 채널. * 반면 전체 미수금의 **88.9%(800,000원)**가 인스타 유입 울쎄라/써마지 환자에게 집중. * ➔ **실행 제언**: 고단가 시술 예약 시 **사전 예약금(Deposit 10~20%) 제도 의무화** 및 당일 수납 완납 프로토콜 도입. 2. **카카오톡 (최우수 충성도 & 이탈률 0%)**: * 총 9건 중 노쇼/취소 0건으로 **진료 완수율 100% 달성** (매출 2,645,000원, 미수 잔금 50,000원). * ➔ **실행 제언**: 주기적 시술 리콜 알림톡 및 지인 추천 프로모션으로 고객 락인(Lock-in) 극대화. 3. **네이버검색 & 당근마켓 (높은 노쇼율 개선 시급)**: * 네이버검색 이탈률 **57.1%**, 당근마켓 이탈률 **40.0%** (전체 이탈의 46.2% 차지). * ➔ **실행 제언**: 예약 전일/당일 카카오 알림톡 자동 재확인 시스템 도입 및 오버부킹 방지를 위한 가변 스케줄링 운영. | C7: • 데이터 추출에 그치지 않고 C-Level 경영진에게 제안할 수 있는 비즈니스 전략 도출 • 지표와 연계된 구체적이고 실행 가능한(Actionable) 솔루션 제시
A8: SEC_06 | B8: --- ## 💻 6. 핵심 SQL 분석 쿼리 (Key SQL Queries) ```sql -- [SQL-01] 일자별 핵심 경영 KPI 요약 쿼리 SELECT Reservation_Date, COUNT(CASE WHEN Reservation_Status = '진료완료' THEN 1 END) AS Completed_Count, SUM(CASE WHEN Reservation_Status = '진료완료' THEN Payment_Amount ELSE 0 END) AS Daily_Revenue, SUM(CASE WHEN Reservation_Status = '진료완료' THEN Unpaid_Amount ELSE 0 END) AS Daily_Unpaid FROM crm_transaction_log GROUP BY Reservation_Date ORDER BY Reservation_Date; -- [SQL-02] 유입 채널별 신환/구환 매출 기여도 및 이탈률 분석 SELECT Inflow_Channel, COUNT(*) AS Total_Reservations, ROUND(SUM(CASE WHEN Is_First_Visit = 'Y' THEN 1 ELSE 0 END) / COUNT(*) * 100, 1) AS New_Patient_Rate, SUM(CASE WHEN Reservation_Status = '진료완료' THEN Payment_Amount ELSE 0 END) AS Revenue, ROUND(SUM(CASE WHEN Reservation_Status IN ('노쇼', '예약취소') THEN 1 ELSE 0 END) / COUNT(*) * 100, 1) AS Drop_Rate FROM crm_transaction_log GROUP BY Inflow_Channel ORDER BY Revenue DESC; ``` | C8: • 실무 수준의 조건부 집계(CASE WHEN, ROUND, GROUP BY) SQL 능력 증명 • MySQL 환경에서 검증 완료된 쿼리 코드 제공
A9: SEC_07 | B9: --- ## 🎯 7. 지원 직무별 차별화 역량 (Role-Fit Summary) * **데이터 분석가 (Data Analyst)**: 트랜잭션 데이터에서 채널별 CAC/LTV 리스크를 발견하고, 지표 기반 전략 수립. * **데이터 운영자 (Data Operator)**: 9건의 데이터 결함을 정제하고 재발 방지 Validation 및 일일 마감 대사 프로세스 확립. * **병원 전산 / EMR 담당자 (Hospital IT)**: RDBMS 스키마 설계, 외래키 무결성 제약조건 및 SQL 기반 데이터 파이프라인 관리. | C9: • 3개 타깃 직무에 맞춘 포지셔닝 완결 • 채용 전형에서 다면 평가 시 일관된 전문성 전달

Sheet crm_transaction_log
A1: Reservation_Date | B1: Reservation_Time | C1: Chart_No | D1: Is_First_Visit | E1: Inflow_Channel | F1: Consultant_ID | G1: Reservation_Status | H1: Treatment_Item | I1: Payment_Amount | J1: Unpaid_Amount | K1: 검증
A2: 46310 | B2: 0.42708333 | C2: C250011 | D2: N | E2: 카카오톡 | F2: CS_01 | G2: 진료완료 | H2: 피코토닝 10회 | I2: 850000 | J2: 0 | K2: =VLOOKUP($C2,customer_master!$A$2:$F$21,1,0) -> C250011 | L2: =IF(OR(G2="예약취소", G2="노쇼"), I2=0, TRUE) -> TRUE | M2: =IF(OR(G2="예약취소", G2="노쇼"), IF(AND(I2=0, J2=0), TRUE, FALSE), TRUE) -> TRUE
A3: 46310 | B3: 0.44444444 | C3: C250012 | D3: N | E3: 재방문 | F3: CS_02 | G3: 진료완료 | H3: 사각턱보톡스 | I3: 45000 | J3: 0 | K3: =VLOOKUP($C3,customer_master!$A$2:$F$21,1,0) -> C250012 | L3: =IF(OR(G3="예약취소", G3="노쇼"), I3=0, TRUE) -> TRUE | M3: =IF(OR(G3="예약취소", G3="노쇼"), IF(AND(I3=0, J3=0), TRUE, FALSE), TRUE) -> TRUE
A4: 46310 | B4: 0.45833333 | C4: C250013 | D4: Y | E4: 지인추천 | F4: CS_01 | G4: 노쇼 | H4: 입술필러 | I4: 0 | J4: 0 | K4: =VLOOKUP($C4,customer_master!$A$2:$F$21,1,0) -> C250013 | L4: =IF(OR(G4="예약취소", G4="노쇼"), I4=0, TRUE) -> TRUE | M4: =IF(OR(G4="예약취소", G4="노쇼"), IF(AND(I4=0, J4=0), TRUE, FALSE), TRUE) -> TRUE
A5: 46310 | B5: 0.47222222 | C5: C250014 | D5: N | E5: 인스타그램 | F5: CS_03 | G5: 진료완료 | H5: 울쎄라 300샷 | I5: 1200000 | J5: 300000 | K5: =VLOOKUP($C5,customer_master!$A$2:$F$21,1,0) -> C250014 | L5: =IF(OR(G5="예약취소", G5="노쇼"), I5=0, TRUE) -> TRUE | M5: =IF(OR(G5="예약취소", G5="노쇼"), IF(AND(I5=0, J5=0), TRUE, FALSE), TRUE) -> TRUE
A6: 46310 | B6: 0.5 | C6: C250015 | D6: Y | E6: 네이버검색 | F6: CS_02 | G6: 진료완료 | H6: 리쥬란힐러 2cc | I6: 290000 | J6: 0 | K6: =VLOOKUP($C6,customer_master!$A$2:$F$21,1,0) -> C250015 | L6: =IF(OR(G6="예약취소", G6="노쇼"), I6=0, TRUE) -> TRUE | M6: =IF(OR(G6="예약취소", G6="노쇼"), IF(AND(I6=0, J6=0), TRUE, FALSE), TRUE) -> TRUE
A7: 46310 | B7: 0.52083333 | C7: C250016 | D7: N | E7: 재방문 | F7: CS_01 | G7: 진료완료 | H7: 겨드랑이제모 5회 | I7: 39000 | J7: 0 | K7: =VLOOKUP($C7,customer_master!$A$2:$F$21,1,0) -> C250016 | L7: =IF(OR(G7="예약취소", G7="노쇼"), I7=0, TRUE) -> TRUE | M7: =IF(OR(G7="예약취소", G7="노쇼"), IF(AND(I7=0, J7=0), TRUE, FALSE), TRUE) -> TRUE
A8: 46310 | B8: 0.58333333 | C8: C250017 | D8: Y | E8: 당근마켓 | F8: CS_03 | G8: 예약취소 | H8: 슈링크 400샷 | I8: 0 | J8: 0 | K8: =VLOOKUP($C8,customer_master!$A$2:$F$21,1,0) -> C250017 | L8: =IF(OR(G8="예약취소", G8="노쇼"), I8=0, TRUE) -> TRUE | M8: =IF(OR(G8="예약취소", G8="노쇼"), IF(AND(I8=0, J8=0), TRUE, FALSE), TRUE) -> TRUE
A9: 46310 | B9: 0.59722222 | C9: C250018 | D9: N | E9: 카카오톡 | F9: CS_02 | G9: 진료완료 | H9: 미간보톡스 | I9: 35000 | J9: 0 | K9: =VLOOKUP($C9,customer_master!$A$2:$F$21,1,0) -> C250018 | L9: =IF(OR(G9="예약취소", G9="노쇼"), I9=0, TRUE) -> TRUE | M9: =IF(OR(G9="예약취소", G9="노쇼"), IF(AND(I9=0, J9=0), TRUE, FALSE), TRUE) -> TRUE
A10: 46310 | B10: 0.63541667 | C10: C250020 | D10: N | E10: 지인추천 | F10: CS_03 | G10: 진료완료 | H10: 인모드 FORMA | I10: 150000 | J10: 0 | K10: =VLOOKUP($C10,customer_master!$A$2:$F$21,1,0) -> C250020 | L10: =IF(OR(G10="예약취소", G10="노쇼"), I10=0, TRUE) -> TRUE | M10: =IF(OR(G10="예약취소", G10="노쇼"), IF(AND(I10=0, J10=0), TRUE, FALSE), TRUE) -> TRUE
A11: 46310 | B11: 0.65277778 | C11: C260021 | D11: Y | E11: 네이버검색 | F11: CS_01 | G11: 노쇼 | H11: 아쿠아필 | I11: 0 | J11: 0 | K11: =VLOOKUP($C11,customer_master!$A$2:$F$21,1,0) -> C260021 | L11: =IF(OR(G11="예약취소", G11="노쇼"), I11=0, TRUE) -> TRUE | M11: =IF(OR(G11="예약취소", G11="노쇼"), IF(AND(I11=0, J11=0), TRUE, FALSE), TRUE) -> TRUE
A12: 46310 | B12: 0.66666667 | C12: C260022 | D12: N | E12: 재방문 | F12: CS_02 | G12: 예약취소 | H12: 피코토닝 10회 | I12: 0 | J12: 0 | K12: =VLOOKUP($C12,customer_master!$A$2:$F$21,1,0) -> C260022 | L12: =IF(OR(G12="예약취소", G12="노쇼"), I12=0, TRUE) -> TRUE | M12: =IF(OR(G12="예약취소", G12="노쇼"), IF(AND(I12=0, J12=0), TRUE, FALSE), TRUE) -> TRUE | N12: 금액삭제(예약취소)
A13: 46310 | B13: 0.68055556 | C13: C260023 | D13: Y | E13: 카카오톡 | F13: CS_03 | G13: 진료완료 | H13: 사각턱보톡스 | I13: 45000 | J13: 0 | K13: =VLOOKUP($C13,customer_master!$A$2:$F$21,1,0) -> C260023 | L13: =IF(OR(G13="예약취소", G13="노쇼"), I13=0, TRUE) -> TRUE | M13: =IF(OR(G13="예약취소", G13="노쇼"), IF(AND(I13=0, J13=0), TRUE, FALSE), TRUE) -> TRUE
A14: 46310 | B14: 0.70833333 | C14: C260024 | D14: N | E14: 지인추천 | F14: CS_01 | G14: 진료완료 | H14: 여드름스케일링 | I14: 60000 | J14: 0 | K14: =VLOOKUP($C14,customer_master!$A$2:$F$21,1,0) -> C260024 | L14: =IF(OR(G14="예약취소", G14="노쇼"), I14=0, TRUE) -> TRUE | M14: =IF(OR(G14="예약취소", G14="노쇼"), IF(AND(I14=0, J14=0), TRUE, FALSE), TRUE) -> TRUE
A15: 46310 | B15: 0.72916667 | C15: C260025 | D15: Y | E15: 인스타그램 | F15: CS_02 | G15: 진료완료 | H15: 팔자필러 | I15: 220000 | J15: 0 | K15: =VLOOKUP($C15,customer_master!$A$2:$F$21,1,0) -> C260025 | L15: =IF(OR(G15="예약취소", G15="노쇼"), I15=0, TRUE) -> TRUE | M15: =IF(OR(G15="예약취소", G15="노쇼"), IF(AND(I15=0, J15=0), TRUE, FALSE), TRUE) -> TRUE
A16: 46310 | B16: 0.75 | C16: C260026 | D16: N | E16: 재방문 | F16: CS_03 | G16: 진료완료 | H16: 써마지 600샷 | I16: 0 | J16: 0 | K16: =VLOOKUP($C16,customer_master!$A$2:$F$21,1,0) -> C260026 | L16: =IF(OR(G16="예약취소", G16="노쇼"), I16=0, TRUE) -> TRUE | M16: =IF(OR(G16="예약취소", G16="노쇼"), IF(AND(I16=0, J16=0), TRUE, FALSE), TRUE) -> TRUE
A17: 46311 | B17: 0.41666667 | C17: C260027 | D17: Y | E17: 당근마켓 | F17: CS_01 | G17: 진료완료 | H17: 쥬베룩 볼륨 | I17: 450000 | J17: 0 | K17: =VLOOKUP($C17,customer_master!$A$2:$F$21,1,0) -> C260027 | L17: =IF(OR(G17="예약취소", G17="노쇼"), I17=0, TRUE) -> TRUE | M17: =IF(OR(G17="예약취소", G17="노쇼"), IF(AND(I17=0, J17=0), TRUE, FALSE), TRUE) -> TRUE
A18: 46311 | B18: 0.4375 | C18: C260028 | D18: N | E18: 네이버검색 | F18: CS_02 | G18: 진료완료 | H18: 피코프락셀 | I18: 120000 | J18: 0 | K18: =VLOOKUP($C18,customer_master!$A$2:$F$21,1,0) -> C260028 | L18: =IF(OR(G18="예약취소", G18="노쇼"), I18=0, TRUE) -> TRUE | M18: =IF(OR(G18="예약취소", G18="노쇼"), IF(AND(I18=0, J18=0), TRUE, FALSE), TRUE) -> TRUE
A19: 46311 | B19: 0.46875 | C19: C260029 | D19: Y | E19: 지인추천 | F19: CS_03 | G19: 노쇼 | H19: 종아리보톡스 | I19: 0 | J19: 0 | K19: =VLOOKUP($C19,customer_master!$A$2:$F$21,1,0) -> C260029 | L19: =IF(OR(G19="예약취소", G19="노쇼"), I19=0, TRUE) -> TRUE | M19: =IF(OR(G19="예약취소", G19="노쇼"), IF(AND(I19=0, J19=0), TRUE, FALSE), TRUE) -> TRUE
A20: 46311 | B20: 0.48958333 | C20: C260030 | D20: N | E20: 재방문 | F20: CS_01 | G20: 진료완료 | H20: 애교필러 | I20: 150000 | J20: 0 | K20: =VLOOKUP($C20,customer_master!$A$2:$F$21,1,0) -> C260030 | L20: =IF(OR(G20="예약취소", G20="노쇼"), I20=0, TRUE) -> TRUE | M20: =IF(OR(G20="예약취소", G20="노쇼"), IF(AND(I20=0, J20=0), TRUE, FALSE), TRUE) -> TRUE
A21: 46311 | B21: 0.52083333 | C21: C250011 | D21: Y | E21: 카카오톡 | F21: CS_02 | G21: 진료완료 | H21: 울쎄라 300샷 | I21: 1200000 | J21: 0 | K21: =VLOOKUP($C21,customer_master!$A$2:$F$21,1,0) -> C250011 | L21: =IF(OR(G21="예약취소", G21="노쇼"), I21=0, TRUE) -> TRUE | M21: =IF(OR(G21="예약취소", G21="노쇼"), IF(AND(I21=0, J21=0), TRUE, FALSE), TRUE) -> TRUE
A22: 46311 | B22: 0.58333333 | C22: C250012 | D22: N | E22: 인스타그램 | F22: CS_03 | G22: 예약취소 | H22: 인중제모 | I22: 0 | J22: 0 | K22: =VLOOKUP($C22,customer_master!$A$2:$F$21,1,0) -> C250012 | L22: =IF(OR(G22="예약취소", G22="노쇼"), I22=0, TRUE) -> TRUE | M22: =IF(OR(G22="예약취소", G22="노쇼"), IF(AND(I22=0, J22=0), TRUE, FALSE), TRUE) -> TRUE
A23: 46311 | B23: 0.61111111 | C23: C250013 | D23: Y | E23: 네이버검색 | F23: CS_01 | G23: 진료완료 | H23: 피코토닝 10회 | I23: 850000 | J23: 50000 | K23: =VLOOKUP($C23,customer_master!$A$2:$F$21,1,0) -> C250013 | L23: =IF(OR(G23="예약취소", G23="노쇼"), I23=0, TRUE) -> TRUE | M23: =IF(OR(G23="예약취소", G23="노쇼"), IF(AND(I23=0, J23=0), TRUE, FALSE), TRUE) -> TRUE
A24: 46311 | B24: 0.625 | C24: C250014 | D24: N | E24: 지인추천 | F24: CS_02 | G24: 진료완료 | H24: 사각턱보톡스 | I24: 45000 | J24: 0 | K24: =VLOOKUP($C24,customer_master!$A$2:$F$21,1,0) -> C250014 | L24: =IF(OR(G24="예약취소", G24="노쇼"), I24=0, TRUE) -> TRUE | M24: =IF(OR(G24="예약취소", G24="노쇼"), IF(AND(I24=0, J24=0), TRUE, FALSE), TRUE) -> TRUE
A25: 46311 | B25: 0.63888889 | C25: C250015 | D25: Y | E25: 당근마켓 | F25: CS_03 | G25: 진료완료 | H25: 입술필러 | I25: 200000 | J25: 0 | K25: =VLOOKUP($C25,customer_master!$A$2:$F$21,1,0) -> C250015 | L25: =IF(OR(G25="예약취소", G25="노쇼"), I25=0, TRUE) -> TRUE | M25: =IF(OR(G25="예약취소", G25="노쇼"), IF(AND(I25=0, J25=0), TRUE, FALSE), TRUE) -> TRUE | N25: 잔금 수정
A26: 46311 | B26: 0.66666667 | C26: C250016 | D26: N | E26: 카카오톡 | F26: CS_01 | G26: 진료완료 | H26: 인모드 FX | I26: 120000 | J26: 0 | K26: =VLOOKUP($C26,customer_master!$A$2:$F$21,1,0) -> C250016 | L26: =IF(OR(G26="예약취소", G26="노쇼"), I26=0, TRUE) -> TRUE | M26: =IF(OR(G26="예약취소", G26="노쇼"), IF(AND(I26=0, J26=0), TRUE, FALSE), TRUE) -> TRUE
A27: 46311 | B27: 0.6875 | C27: C250017 | D27: Y | E27: 재방문 | F27: CS_02 | G27: 예약취소 | H27: 리쥬란힐러 2cc | I27: 0 | J27: 0 | K27: =VLOOKUP($C27,customer_master!$A$2:$F$21,1,0) -> C250017 | L27: =IF(OR(G27="예약취소", G27="노쇼"), I27=0, TRUE) -> TRUE | M27: =IF(OR(G27="예약취소", G27="노쇼"), IF(AND(I27=0, J27=0), TRUE, FALSE), TRUE) -> TRUE | N27: 잔금삭제
A28: 46311 | B28: 0.70833333 | C28: C250018 | D28: N | E28: 네이버검색 | F28: CS_03 | G28: 노쇼 | H28: 겨드랑이제모 5회 | I28: 0 | J28: 0 | K28: =VLOOKUP($C28,customer_master!$A$2:$F$21,1,0) -> C250018 | L28: =IF(OR(G28="예약취소", G28="노쇼"), I28=0, TRUE) -> TRUE | M28: =IF(OR(G28="예약취소", G28="노쇼"), IF(AND(I28=0, J28=0), TRUE, FALSE), TRUE) -> TRUE
A29: 46311 | B29: 0.73611111 | C29: C250019 | D29: Y | E29: 지인추천 | F29: CS_01 | G29: 진료완료 | H29: 피코프락셀 | I29: 120000 | J29: 0 | K29: =VLOOKUP($C29,customer_master!$A$2:$F$21,1,0) -> C250019 | L29: =IF(OR(G29="예약취소", G29="노쇼"), I29=0, TRUE) -> TRUE | M29: =IF(OR(G29="예약취소", G29="노쇼"), IF(AND(I29=0, J29=0), TRUE, FALSE), TRUE) -> TRUE
A30: 46312 | B30: 0.41666667 | C30: C250020 | D30: N | E30: 인스타그램 | F30: CS_02 | G30: 진료완료 | H30: 미간보톡스 | I30: 35000 | J30: 0 | K30: =VLOOKUP($C30,customer_master!$A$2:$F$21,1,0) -> C250020 | L30: =IF(OR(G30="예약취소", G30="노쇼"), I30=0, TRUE) -> TRUE | M30: =IF(OR(G30="예약취소", G30="노쇼"), IF(AND(I30=0, J30=0), TRUE, FALSE), TRUE) -> TRUE
A31: 46312 | B31: 0.42708333 | C31: C260021 | D31: Y | E31: 카카오톡 | F31: CS_03 | G31: 진료완료 | H31: 코필러 | I31: 180000 | J31: 50000 | K31: =VLOOKUP($C31,customer_master!$A$2:$F$21,1,0) -> C260021 | L31: =IF(OR(G31="예약취소", G31="노쇼"), I31=0, TRUE) -> TRUE | M31: =IF(OR(G31="예약취소", G31="노쇼"), IF(AND(I31=0, J31=0), TRUE, FALSE), TRUE) -> TRUE
A32: 46312 | B32: 0.45833333 | C32: C260022 | D32: N | E32: 재방문 | F32: CS_01 | G32: 진료완료 | H32: 울쎄라 600샷 | I32: 2200000 | J32: 0 | K32: =VLOOKUP($C32,customer_master!$A$2:$F$21,1,0) -> C260022 | L32: =IF(OR(G32="예약취소", G32="노쇼"), I32=0, TRUE) -> TRUE | M32: =IF(OR(G32="예약취소", G32="노쇼"), IF(AND(I32=0, J32=0), TRUE, FALSE), TRUE) -> TRUE
A33: 46312 | B33: 0.47916667 | C33: C260023 | D33: Y | E33: 네이버검색 | F33: CS_02 | G33: 예약취소 | H33: 슈링크 400샷 | I33: 0 | J33: 0 | K33: =VLOOKUP($C33,customer_master!$A$2:$F$21,1,0) -> C260023 | L33: =IF(OR(G33="예약취소", G33="노쇼"), I33=0, TRUE) -> TRUE | M33: =IF(OR(G33="예약취소", G33="노쇼"), IF(AND(I33=0, J33=0), TRUE, FALSE), TRUE) -> TRUE
A34: 46312 | B34: 0.5 | C34: C260024 | D34: N | E34: 지인추천 | F34: CS_03 | G34: 진료완료 | H34: 종아리제모 | I34: 80000 | J34: 0 | K34: =VLOOKUP($C34,customer_master!$A$2:$F$21,1,0) -> C260024 | L34: =IF(OR(G34="예약취소", G34="노쇼"), I34=0, TRUE) -> TRUE | M34: =IF(OR(G34="예약취소", G34="노쇼"), IF(AND(I34=0, J34=0), TRUE, FALSE), TRUE) -> TRUE
A35: 46312 | B35: 0.54166667 | C35: C260025 | D35: Y | E35: 당근마켓 | F35: CS_01 | G35: 노쇼 | H35: 피코토닝 10회 | I35: 0 | J35: 0 | K35: =VLOOKUP($C35,customer_master!$A$2:$F$21,1,0) -> C260025 | L35: =IF(OR(G35="예약취소", G35="노쇼"), I35=0, TRUE) -> TRUE | M35: =IF(OR(G35="예약취소", G35="노쇼"), IF(AND(I35=0, J35=0), TRUE, FALSE), TRUE) -> TRUE
A36: 46312 | B36: 0.5625 | C36: C260026 | D36: N | E36: 카카오톡 | F36: CS_02 | G36: 진료완료 | H36: 사각턱보톡스 | I36: 45000 | J36: 0 | K36: =VLOOKUP($C36,customer_master!$A$2:$F$21,1,0) -> C260026 | L36: =IF(OR(G36="예약취소", G36="노쇼"), I36=0, TRUE) -> TRUE | M36: =IF(OR(G36="예약취소", G36="노쇼"), IF(AND(I36=0, J36=0), TRUE, FALSE), TRUE) -> TRUE
A37: 46312 | B37: 0.58333333 | C37: C260027 | D37: Y | E37: 재방문 | F37: CS_03 | G37: 진료완료 | H37: 팔자필러 | I37: 220000 | J37: 0 | K37: =VLOOKUP($C37,customer_master!$A$2:$F$21,1,0) -> C260027 | L37: =IF(OR(G37="예약취소", G37="노쇼"), I37=0, TRUE) -> TRUE | M37: =IF(OR(G37="예약취소", G37="노쇼"), IF(AND(I37=0, J37=0), TRUE, FALSE), TRUE) -> TRUE
A38: 46312 | B38: 0.61458333 | C38: C260028 | D38: N | E38: 인스타그램 | F38: CS_01 | G38: 진료완료 | H38: 써마지 600샷 | I38: 2500000 | J38: 500000 | K38: =VLOOKUP($C38,customer_master!$A$2:$F$21,1,0) -> C260028 | L38: =IF(OR(G38="예약취소", G38="노쇼"), I38=0, TRUE) -> TRUE | M38: =IF(OR(G38="예약취소", G38="노쇼"), IF(AND(I38=0, J38=0), TRUE, FALSE), TRUE) -> TRUE
A39: 46312 | B39: 0.63541667 | C39: C260029 | D39: Y | E39: 지인추천 | F39: CS_02 | G39: 진료완료 | H39: 쥬베룩 볼륨 | I39: 450000 | J39: 0 | K39: =VLOOKUP($C39,customer_master!$A$2:$F$21,1,0) -> C260029 | L39: =IF(OR(G39="예약취소", G39="노쇼"), I39=0, TRUE) -> TRUE | M39: =IF(OR(G39="예약취소", G39="노쇼"), IF(AND(I39=0, J39=0), TRUE, FALSE), TRUE) -> TRUE
A40: 46312 | B40: 0.66666667 | C40: C250011 | D40: Y | E40: 카카오톡 | F40: CS_01 | G40: 진료완료 | H40: 피코프락셀 | I40: 120000 | J40: 0 | K40: =VLOOKUP($C40,customer_master!$A$2:$F$21,1,0) -> C250011 | L40: =IF(OR(G40="예약취소", G40="노쇼"), I40=0, TRUE) -> TRUE | M40: =IF(OR(G40="예약취소", G40="노쇼"), IF(AND(I40=0, J40=0), TRUE, FALSE), TRUE) -> TRUE
...

Sheet customer_master
A1: Chart_No | B1: Customer_ID | C1: Customer_Name | D1: Phone_Number | E1: Customer_Grade | F1: Join_Date
A2: C250011 | B2: U1011 | C2: 김*수 | D2: 010-1234-5678 | E2: VIP | F2: 45667
A3: C250012 | B3: U1012 | C3: 이*영 | D3: 010-2345-6789 | E3: 일반 | F3: 45703
A4: C250013 | B4: U1013 | C4: 박*진 | D4: 010-3456-7890 | E4: 우수 | F4: 45717
A5: C250014 | B5: U1014 | C5: 최*훈 | D5: 010-4567-8901 | E5: 일반 | F5: 45757
A6: C250015 | B6: U1015 | C6: 정*아 | D6: 010-5678-9012 | E6: VIP | F6: 45782
A7: C250016 | B7: U1016 | C7: 강*석 | D7: 010-6789-0123 | E7: 우수 | F7: 45828
A8: C250017 | B8: U1017 | C8: 조*희 | D8: 010-7890-1234 | E8: 일반 | F8: 45839
A9: C250018 | B9: U1018 | C9: 윤*미 | D9: 010-8901-2345 | E9: 일반 | F9: 45884
A10: C250019 | B10: U1019 | C10: 장*민 | D10: 010-9012-3456 | E10: 우수 | F10: 45901
A11: C250020 | B11: U1020 | C11: 임*주 | D11: 010-0123-4567 | E11: VIP | F11: 45940
A12: C260021 | B12: U1021 | C12: 한*수 | D12: 010-1111-2222 | E12: 일반 | F12: 46027
A13: C260022 | B13: U1022 | C13: 오*연 | D13: 010-2222-3333 | E13: 일반 | F13: 46067
... A21: C260030 | B21: U1030 | C21: 고*석 | D21: 010-0000-1111 | E21: 우수 | F21: 46296

Sheet RAW_DATA
A1: Reservation_Date | B1: Reservation_Time | C1: Chart_No | D1: Is_First_Visit | E1: Inflow_Channel | F1: Consultant_ID | G1: Reservation_Status | H1: Treatment_Item | I1: Payment_Amount | J1: Unpaid_Amount | K1: 검증
A2: 46310 | B2: 0.42708333 | C2: C250011 | D2: N | E2: 카카오톡 | F2: CS_01 | G2: 진료완료 | H2: 피코토닝 10회 | I2: 850000 | J2: 0 | K2: =VLOOKUP($C2,customer_master!$A$2:$F$21,1,0) -> C250011 | L2: =IF(OR(G2="예약취소", G2="노쇼"), I2=0, TRUE) -> TRUE | M2: =IF(OR(G2="예약취소", G2="노쇼"), IF(AND(I2=0, J2=0), TRUE, FALSE), TRUE) -> TRUE
A3: 46310 | B3: 0.44444444 | C3: C250012 | D3: N | E3: 재방문 | F3: CS_02 | G3: 진료완료 | H3: 사각턱보톡스 | I3: 45000 | J3: 0 | K3: =VLOOKUP($C3,customer_master!$A$2:$F$21,1,0) -> C250012 | L3: =IF(OR(G3="예약취소", G3="노쇼"), I3=0, TRUE) -> TRUE | M3: =IF(OR(G3="예약취소", G3="노쇼"), IF(AND(I3=0, J3=0), TRUE, FALSE), TRUE) -> TRUE
A4: 46310 | B4: 0.45833333 | C4: C250013 | D4: Y | E4: 지인추천 | F4: CS_01 | G4: 노쇼 | H4: 입술필러 | I4: 0 | J4: 0 | K4: =VLOOKUP($C4,customer_master!$A$2:$F$21,1,0) -> C250013 | L4: =IF(OR(G4="예약취소", G4="노쇼"), I4=0, TRUE) -> TRUE | M4: =IF(OR(G4="예약취소", G4="노쇼"), IF(AND(I4=0, J4=0), TRUE, FALSE), TRUE) -> TRUE
A5: 46310 | B5: 0.47222222 | C5: C250014 | D5: N | E5: 인스타그램 | F5: CS_03 | G5: 진료완료 | H5: 울쎄라 300샷 | I5: 1200000 | J5: 300000 | K5: =VLOOKUP($C5,customer_master!$A$2:$F$21,1,0) -> C250014 | L5: =IF(OR(G5="예약취소", G5="노쇼"), I5=0, TRUE) -> TRUE | M5: =IF(OR(G5="예약취소", G5="노쇼"), IF(AND(I5=0, J5=0), TRUE, FALSE), TRUE) -> TRUE
A6: 46310 | B6: 0.5 | C6: C250015 | D6: Y | E6: 네이버검색 | F6: CS_02 | G6: 진료완료 | H6: 리쥬란힐러 2cc | I6: 290000 | J6: 0 | K6: =VLOOKUP($C6,customer_master!$A$2:$F$21,1,0) -> C250015 | L6: =IF(OR(G6="예약취소", G6="노쇼"), I6=0, TRUE) -> TRUE | M6: =IF(OR(G6="예약취소", G6="노쇼"), IF(AND(I6=0, J6=0), TRUE, FALSE), TRUE) -> TRUE
A7: 46310 | B7: 0.52083333 | C7: C250016 | D7: N | E7: 재방문 | F7: CS_01 | G7: 진료완료 | H7: 겨드랑이제모 5회 | I7: 39000 | J7: 0 | K7: =VLOOKUP($C7,customer_master!$A$2:$F$21,1,0) -> C250016 | L7: =IF(OR(G7="예약취소", G7="노쇼"), I7=0, TRUE) -> TRUE | M7: =IF(OR(G7="예약취소", G7="노쇼"), IF(AND(I7=0, J7=0), TRUE, FALSE), TRUE) -> TRUE
A8: 46310 | B8: 0.58333333 | C8: C250017 | D8: Y | E8: 당근마켓 | F8: CS_03 | G8: 예약취소 | H8: 슈링크 400샷 | I8: 0 | J8: 0 | K8: =VLOOKUP($C8,customer_master!$A$2:$F$21,1,0) -> C250017 | L8: =IF(OR(G8="예약취소", G8="노쇼"), I8=0, TRUE) -> TRUE | M8: =IF(OR(G8="예약취소", G8="노쇼"), IF(AND(I8=0, J8=0), TRUE, FALSE), TRUE) -> TRUE
A9: 46310 | B9: 0.59722222 | C9: C250018 | D9: N | E9: 카카오톡 | F9: CS_02 | G9: 진료완료 | H9: 미간보톡스 | I9: 35000 | J9: 0 | K9: =VLOOKUP($C9,customer_master!$A$2:$F$21,1,0) -> C250018 | L9: =IF(OR(G9="예약취소", G9="노쇼"), I9=0, TRUE) -> TRUE | M9: =IF(OR(G9="예약취소", G9="노쇼"), IF(AND(I9=0, J9=0), TRUE, FALSE), TRUE) -> TRUE
A10: 46310 | B10: 0.63541667 | C10: C250020 | D10: N | E10: 지인추천 | F10: CS_03 | G10: 진료완료 | H10: 인모드 FORMA | I10: 150000 | J10: 0 | K10: =VLOOKUP($C10,customer_master!$A$2:$F$21,1,0) -> C250020 | L10: =IF(OR(G10="예약취소", G10="노쇼"), I10=0, TRUE) -> TRUE | M10: =IF(OR(G10="예약취소", G10="노쇼"), IF(AND(I10=0, J10=0), TRUE, FALSE), TRUE) -> TRUE
A11: 46310 | B11: 0.65277778 | C11: C260021 | D11: Y | E11: 네이버검색 | F11: CS_01 | G11: 노쇼 | H11: 아쿠아필 | I11: 0 | J11: 0 | K11: =VLOOKUP($C11,customer_master!$A$2:$F$21,1,0) -> C260021 | L11: =IF(OR(G11="예약취소", G11="노쇼"), I11=0, TRUE) -> TRUE | M11: =IF(OR(G11="예약취소", G11="노쇼"), IF(AND(I11=0, J11=0), TRUE, FALSE), TRUE) -> TRUE
A12: 46310 | B12: 0.66666667 | C12: C260022 | D12: N | E12: 재방문 | F12: CS_02 | G12: 예약취소 | H12: 피코토닝 10회 | I12: 0 | J12: 0 | K12: =VLOOKUP($C12,customer_master!$A$2:$F$21,1,0) -> C260022 | L12: =IF(OR(G12="예약취소", G12="노쇼"), I12=0, TRUE) -> TRUE | M12: =IF(OR(G12="예약취소", G12="노쇼"), IF(AND(I12=0, J12=0), TRUE, FALSE), TRUE) -> TRUE | N12: 금액삭제(예약취소)
A13: 46310 | B13: 0.68055556 | C13: C260023 | D13: Y | E13: 카카오톡 | F13: CS_03 | G13: 진료완료 | H13: 사각턱보톡스 | I13: 45000 | J13: 0 | K13: =VLOOKUP($C13,customer_master!$A$2:$F$21,1,0) -> C260023 | L13: =IF(OR(G13="예약취소", G13="노쇼"), I13=0, TRUE) -> TRUE | M13: =IF(OR(G13="예약취소", G13="노쇼"), IF(AND(I13=0, J13=0), TRUE, FALSE), TRUE) -> TRUE
A14: 46310 | B14: 0.70833333 | C14: C260024 | D14: N | E14: 지인추천 | F14: CS_01 | G14: 진료완료 | H14: 여드름스케일링 | I14: 60000 | J14: 0 | K14: =VLOOKUP($C14,customer_master!$A$2:$F$21,1,0) -> C260024 | L14: =IF(OR(G14="예약취소", G14="노쇼"), I14=0, TRUE) -> TRUE | M14: =IF(OR(G14="예약취소", G14="노쇼"), IF(AND(I14=0, J14=0), TRUE, FALSE), TRUE) -> TRUE
A15: 46310 | B15: 0.72916667 | C15: C260025 | D15: Y | E15: 인스타그램 | F15: CS_02 | G15: 진료완료 | H15: 팔자필러 | I15: 220000 | J15: 0 | K15: =VLOOKUP($C15,customer_master!$A$2:$F$21,1,0) -> C260025 | L15: =IF(OR(G15="예약취소", G15="노쇼"), I15=0, TRUE) -> TRUE | M15: =IF(OR(G15="예약취소", G15="노쇼"), IF(AND(I15=0, J15=0), TRUE, FALSE), TRUE) -> TRUE
A16: 46310 | B16: 0.75 | C16: C260026 | D16: N | E16: 재방문 | F16: CS_03 | G16: 진료완료 | H16: 써마지 600샷 | I16: 0 | J16: 0 | K16: =VLOOKUP($C16,customer_master!$A$2:$F$21,1,0) -> C260026 | L16: =IF(OR(G16="예약취소", G16="노쇼"), I16=0, TRUE) -> TRUE | M16: =IF(OR(G16="예약취소", G16="노쇼"), IF(AND(I16=0, J16=0), TRUE, FALSE), TRUE) -> TRUE
A17: 46311 | B17: 0.41666667 | C17: C260027 | D17: Y | E17: 당근마켓 | F17: CS_01 | G17: 진료완료 | H17: 쥬베룩 볼륨 | I17: 450000 | J17: 0 | K17: =VLOOKUP($C17,customer_master!$A$2:$F$21,1,0) -> C260027 | L17: =IF(OR(G17="예약취소", G17="노쇼"), I17=0, TRUE) -> TRUE | M17: =IF(OR(G17="예약취소", G17="노쇼"), IF(AND(I17=0, J17=0), TRUE, FALSE), TRUE) -> TRUE
A18: 46311 | B18: 0.4375 | C18: C260028 | D18: N | E18: 네이버검색 | F18: CS_02 | G18: 진료완료 | H18: 피코프락셀 | I18: 120000 | J18: 0 | K18: =VLOOKUP($C18,customer_master!$A$2:$F$21,1,0) -> C260028 | L18: =IF(OR(G18="예약취소", G18="노쇼"), I18=0, TRUE) -> TRUE | M18: =IF(OR(G18="예약취소", G18="노쇼"), IF(AND(I18=0, J18=0), TRUE, FALSE), TRUE) -> TRUE
A19: 46311 | B19: 0.46875 | C19: C260029 | D19: Y | E19: 지인추천 | F19: CS_03 | G19: 노쇼 | H19: 종아리보톡스 | I19: 0 | J19: 0 | K19: =VLOOKUP($C19,customer_master!$A$2:$F$21,1,0) -> C260029 | L19: =IF(OR(G19="예약취소", G19="노쇼"), I19=0, TRUE) -> TRUE | M19: =IF(OR(G19="예약취소", G19="노쇼"), IF(AND(I19=0, J19=0), TRUE, FALSE), TRUE) -> TRUE
A20: 46311 | B20: 0.48958333 | C20: C260030 | D20: N | E20: 재방문 | F20: CS_01 | G20: 진료완료 | H20: 애교필러 | I20: 150000 | J20: 0 | K20: =VLOOKUP($C20,customer_master!$A$2:$F$21,1,0) -> C260030 | L20: =IF(OR(G20="예약취소", G20="노쇼"), I20=0, TRUE) -> TRUE | M20: =IF(OR(G20="예약취소", G20="노쇼"), IF(AND(I20=0, J20=0), TRUE, FALSE), TRUE) -> TRUE
A21: 46311 | B21: 0.52083333 | C21: C250011 | D21: Y | E21: 카카오톡 | F21: CS_02 | G21: 진료완료 | H21: 울쎄라 300샷 | I21: 1200000 | J21: 0 | K21: =VLOOKUP($C21,customer_master!$A$2:$F$21,1,0) -> C250011 | L21: =IF(OR(G21="예약취소", G21="노쇼"), I21=0, TRUE) -> TRUE | M21: =IF(OR(G21="예약취소", G21="노쇼"), IF(AND(I21=0, J21=0), TRUE, FALSE), TRUE) -> TRUE
A22: 46311 | B22: 0.58333333 | C22: C250012 | D22: N | E22: 인스타그램 | F22: CS_03 | G22: 예약취소 | H22: 인중제모 | I22: 0 | J22: 0 | K22: =VLOOKUP($C22,customer_master!$A$2:$F$21,1,0) -> C250012 | L22: =IF(OR(G22="예약취소", G22="노쇼"), I22=0, TRUE) -> TRUE | M22: =IF(OR(G22="예약취소", G22="노쇼"), IF(AND(I22=0, J22=0), TRUE, FALSE), TRUE) -> TRUE
A23: 46311 | B23: 0.61111111 | C23: C250013 | D23: Y | E23: 네이버검색 | F23: CS_01 | G23: 진료완료 | H23: 피코토닝 10회 | I23: 850000 | J23: 50000 | K23: =VLOOKUP($C23,customer_master!$A$2:$F$21,1,0) -> C250013 | L23: =IF(OR(G23="예약취소", G23="노쇼"), I23=0, TRUE) -> TRUE | M23: =IF(OR(G23="예약취소", G23="노쇼"), IF(AND(I23=0, J23=0), TRUE, FALSE), TRUE) -> TRUE
A24: 46311 | B24: 0.625 | C24: C250014 | D24: N | E24: 지인추천 | F24: CS_02 | G24: 진료완료 | H24: 사각턱보톡스 | I24: 45000 | J24: 0 | K24: =VLOOKUP($C24,customer_master!$A$2:$F$21,1,0) -> C250014 | L24: =IF(OR(G24="예약취소", G24="노쇼"), I24=0, TRUE) -> TRUE | M24: =IF(OR(G24="예약취소", G24="노쇼"), IF(AND(I24=0, J24=0), TRUE, FALSE), TRUE) -> TRUE
A25: 46311 | B25: 0.63888889 | C25: C250015 | D25: Y | E25: 당근마켓 | F25: CS_03 | G25: 진료완료 | H25: 입술필러 | I25: 200000 | J25: 0 | K25: =VLOOKUP($C25,customer_master!$A$2:$F$21,1,0) -> C250015 | L25: =IF(OR(G25="예약취소", G25="노쇼"), I25=0, TRUE) -> TRUE | M25: =IF(OR(G25="예약취소", G25="노쇼"), IF(AND(I25=0, J25=0), TRUE, FALSE), TRUE) -> TRUE | N25: 잔금 수정
A26: 46311 | B26: 0.66666667 | C26: C250016 | D26: N | E26: 카카오톡 | F26: CS_01 | G26: 진료완료 | H26: 인모드 FX | I26: 120000 | J26: 0 | K26: =VLOOKUP($C26,customer_master!$A$2:$F$21,1,0) -> C250016 | L26: =IF(OR(G26="예약취소", G26="노쇼"), I26=0, TRUE) -> TRUE | M26: =IF(OR(G26="예약취소", G26="노쇼"), IF(AND(I26=0, J26=0), TRUE, FALSE), TRUE) -> TRUE
